Workbook

Sheet 1-Base Plate
A1: MOHAMED MUSTAFA | Steel Structures Design | L1: DESIGN BY : | M1: ENG. Mohamed Mustafa | P1: REV. NO. : | Q1: 3 | R1: DATE OF REV : | T1: 45940
A2: Column Base Plate & Anchor Bolt Forces - ECP 205 (ASD / LRFD) | L2: Phone | M2: ="01140949980" -> 01140949980 | P2: WhatsApp
A3: DESIGN BY : | B3: ENG. Mohamed Mustafa | L3: Linkedin account | P3: Facebook account
A4: Project ID. : | L4: Portfolio
A6: Data Entry
A8: Design Method : | C8: ASD
A9: Forces Input : | C9: Column
A10: Column Section : | C10: I-Section
A11: Moment About : | C11: Major
A12: Section Depth h = | C12: 400 | D12: mm
A13: Section Width b = | C13: 200 | D13: mm
A14: Flange tf = | C14: 14 | D14: mm
A15: Web tw = | C15: 8 | D15: mm
A16: Plate Steel : | C16: ST 37
A17: Base Plate Lx = | C17: 60 | D17: cm
A18: Base Plate Ly = | C18: 30 | D18: cm
A19: Plate Thickness = | C19: 4 | D19: cm
A20: Weld Type : | C20: Fillet
A21: Weld Size s = | C21: 12 | D21: mm
A22: Concrete Fcu = | C22: 250 | D22: kg/cm2
A23: Pedestal Bx = | C23: 80 | D23: cm
A24: Pedestal By = | C24: 60 | D24: cm
A25: Bolt Ø (sheet 2) = | C25: ='2-Anchor Bolt'!C12 -> 30 | D25: mm
A26: Base Plate : | C26: =IF($W$61,"By IDEA",IF(AND($W$128,OR(F89="Safe",F89="N/A"),F96="Safe",F101="Safe",OR($W$88<>"C",ISNUMBER($W$90))),"Safe","Check design steps")) -> Safe
E27: Plan to scale - updates with the inputs:
A28: =IF($C$8="ASD","Column Forces (service) :","Column Forces (factored) :") -> Column Forces (service) : | E28: ⊕ bolt ( X , Y ) in cm
A29: Axial Force N = | C29: 20 | D29: ton | E29: ▬ pedestal - - - base plate
A30: N is : | C30: Compression | E30: ▬ column profile
A31: Moment M = | C31: 8 | D31: t.m | E31: - - - neutral axis (red)
A32: Shear Vx = | C32: 3 | D32: ton | E32: //// compression zone under the plate
A33: Shear Vy = | C33: 1 | D33: ton
A34: (+) M compresses the +X side (Major) / +Y side (Minor)
A35: Anchor Bolts Layout : | D35: =IF($C$9="IDEA","Forces per bolt (from IDEA)","IDEA only - not used") -> IDEA only - not used
A36: Bolt No. | B36: X (cm) | C36: Y (cm) | D36: T (ton) | E36: Vx (ton) | F36: Vy (ton) | V36: act | W36: x | X36: y | Y36: u | Z36: d | AA36: T stat | AB36: T | AC36: Vx | AD36: Vy | AE36: V | AF36: |x| | AG36: |y| | AH36: outX | AI36: outY | AJ36: r | AK36: dirX | AL36: b web | AM36: b fl | AN36: b raw | AO36: a raw | AP36: w | AQ36: b | AR36: a | AS36: z | AT36: Q | AU36: T+Q | AV36: Mt/w | AW36: cx | AX36: cy | AY36: c | BA36: pair distances | BM36: in plate
A37: 1 | B37: -25 | C37: -10 | V37: =AND(ISNUMBER(B37),ISNUMBER(C37)) -> TRUE | W37: =IF(V37,B37,0) -> -25 | X37: =IF(V37,C37,0) -> -10 | Y37: =IF($W$64,W37,X37) -> -25 | Z37: =IF(V37,$W$71/2-$W$75*Y37,-1) -> 55 | AA37: =IF(V37,IF($W$88="B",$W$86+$W$85*(Z37-$W$82),IF($W$88="C",$W$93*$W$81*MAX(Z37-$W$90,0),0)),0) -> 4.0587297 | AB37: =IF(V37,IF($W$61,MAX(0,N(D37)),MAX(0,AA37)),0) -> 4.0587297 | AC37: =IF(V37,IF($W$61,ABS(N(E37)),ABS(N($C$32))/$W$77),0) -> 0.75 | AD37: =IF(V37,IF($W$61,ABS(N(F37)),ABS(N($C$33))/$W$77),0) -> 0.25 | AE37: =SQRT(AC37^2+AD37^2) -> 0.79056942 | AF37: =ABS(W37) -> 25 | AG37: =ABS(X37) -> 10 | AH37: =AF37>$W$69 -> TRUE | AI37: =AG37>$W$70 -> FALSE | AJ37: =SQRT(W37^2+X37^2) -> 26.925824 | AK37: =IF(AND(AH37,AI37),$W$64,AH37) -> TRUE | AL37: =IF($W$63,AG37-$W$68/2,($W$70-$W$68)-AG37) -> 9.6 | AM37: =($W$69-$W$67)-AF37 -> -6.4 | AN37: =IF($W$62,IF(AJ37>$W$65/2,AJ37-$W$65/2,$W$65/2-$W$67-AJ37),IF(OR(AH37,AI37),IF(AK37,AF37-$W$69,AG37-$W$70),MIN(AL37,AM37))) -> 5 | AO37: =IF($W$62,IF(AJ37>$W$65/2,MIN($C$17/2-AF37,$C$18/2-AG37),1.25*AN37),IF(OR(AH37,AI37),IF(AK37,$C$17/2-AF37,$C$18/2-AG37),IF(AND(AL37<=AM37,$W$63),$C$18/2-AG37,1.25*AN37))) -> 5 | AP37: =IF(V37,IF($W$62,2*PI()*MAX(AJ37,0.1)/$W$77,IF(OR(AH37,AI37),IF(AK37,$C$18/SUMPRODUCT(--($V$37:$V$48),--($W$37:$W$48=W37)),$C$17/SUMPRODUCT(--($V$37:$V$48),--($X$37:$X$48=X37))),IF(AL37<=AM37,($W$65-2*$W$67)/SUMPRODUCT(--($V$37:$V$48),--($X$37:$X$48=X37)),IF($W$63,$W$66,$W$66-2*$W$68)/SUMPRODUCT(--($V$37:$V$48),--($W$37:$W$48=W37))))),1) -> 15 | AQ37: =MAX(0.1,AN37) -> 5 | AR37: =MAX(0.1,MIN(AO37,1.25*AQ37)) -> 5 | AS37: =AP37*$C$19^4/(AR37*AQ37^2*$W$78) -> 5.5717833 | AT37: =IF(AND(V37,NOT($W$61),AB37>0),MAX(0,AB37*(0.5-AS37/30)/((3*AR37/(4*AQ37)+1)*(AR37/(3*AQ37)+1)+AS37/6)),0) -> 0.39103829 | AU37: =AB37+AT37 -> 4.449768 | AV37: =IF(AB37>0,MAX(AB37*AQ37-AT37*AR37,AT37*AR37)/AP37,0) -> 1.2225638 | AW37: =$C$23/2-AF37 -> 15 | AX37: =$C$24/2-AG37 -> 20 | AY37: =IF(V37,MIN(AW37,AX37),"") -> 15 | BB37: =IF(AND(V37,V38),SQRT((W37-W38)^2+(X37-X38)^2),"") -> 50 | BC37: =IF(AND(V37,V39),SQRT((W37-W39)^2+(X37-X39)^2),"") -> 53.851648 | BD37: =IF(AND(V37,V40),SQRT((W37-W40)^2+(X37-X40)^2),"") -> 20 | BE37: =IF(AND(V37,V41),SQRT((W37-W41)^2+(X37-X41)^2),"") | BF37: =IF(AND(V37,V42),SQRT((W37-W42)^2+(X37-X42)^2),"") | BG37: =IF(AND(V37,V43),SQRT((W37-W43)^2+(X37-X43)^2),"") | BH37: =IF(AND(V37,V44),SQRT((W37-W44)^2+(X37-X44)^2),"") | BI37: =IF(AND(V37,V45),SQRT((W37-W45)^2+(X37-X45)^2),"") | BJ37: =IF(AND(V37,V46),SQRT((W37-W46)^2+(X37-X46)^2),"") | BK37: =IF(AND(V37,V47),SQRT((W37-W47)^2+(X37-X47)^2),"") | BL37: =IF(AND(V37,V48),SQRT((W37-W48)^2+(X37-X48)^2),"") | BM37: =IF(V37,AND(AF37<=$C$17/2-1.5*'2-Anchor Bolt'!$C$12/10,AG37<=$C$18/2-1.5*'2-Anchor Bolt'!$C$12/10),TRUE) -> TRUE | BP37: =-1*$C$23/2/$W$126 -> -0.83333333 | BQ37: =-1*$C$24/2/$W$126 -> -0.625 | BR37: =-1*$C$17/2/$W$126 -> -0.625 | BS37: =-1*$C$18/2/$W$126 -> -0.3125 | BT37: =IF($W$62,$W$69*COS((2*PI()*0/36)),IF($W$63,(-1*$W$69+(0)*$W$67),-1*$W$69))/$W$126 -> -0.41666667 | BU37: =IF($W$62,$W$69*SIN((2*PI()*0/36)),IF($W$63,(-1*$W$70),-1*$W$70))/$W$126 -> -0.20833333 | BV37: =IF($W$62,($W$69-$W$67)*COS((2*PI()*0/36)),IF($W$63,-$W$69,-1*($W$69-$W$67)))/$W$126 -> -0.41666667 | BW37: =IF($W$62,($W$69-$W$67)*SIN((2*PI()*0/36)),IF($W$63,-$W$70,-1*($W$70-$W$68)))/$W$126 -> -0.20833333 | BX37: =-($C$23/2+5)/$W$126 -> -0.9375 | BY37: 0 | CH37: =IF(AND($W$88="C",ISNUMBER($W$127)),IF($W$64,$W$127,-1*$C$17/2*1.1),NA())/$W$126 -> 0.077231367 | CI37: =IF(AND($W$88="C",ISNUMBER($W$127)),IF($W$64,-1*$C$18/2*1.1,$W$127),NA())/$W$126 -> -0.34375 | CJ37: =IF(OR($W$88="A",AND($W$88="C",ISNUMBER($W$127))),IF($W$64,$W$75*$W$71/2,(-$W$72/2+$W$72*0/20)),NA())/$W$126 -> 0.625 | CK37: =IF(OR($W$88="A",AND($W$88="C",ISNUMBER($W$127))),IF($W$64,(-$W$72/2+$W$72*0/20),$W$75*$W$71/2),NA())/$W$126 -> -0.3125 | CL37: =IF(V37,W37/$W$126,NA()) -> -0.52083333 | CM37: =IF(V37,X37/$W$126,NA()) -> -0.20833333 | CN37: =IF(V37,"("&TEXT(W37,"0.0")&" , "&TEXT(X37,"0.0")&")","") -> (-25.0 , -10.0) | CO37: =($C$23/2+5)/$W$126 -> 0.9375 | CP37: 0 | CQ37: X
A38: 2 | B38: 25 | C38: -10 | V38: =AND(ISNUMBER(B38),ISNUMBER(C38)) -> TRUE | W38: =IF(V38,B38,0) -> 25 | X38: =IF(V38,C38,0) -> -10 | Y38: =IF($W$64,W38,X38) -> 25 | Z38: =IF(V38,$W$71/2-$W$75*Y38,-1) -> 5 | AA38: =IF(V38,IF($W$88="B",$W$86+$W$85*(Z38-$W$82),IF($W$88="C",$W$93*$W$81*MAX(Z38-$W$90,0),0)),0) -> 0 | AB38: =IF(V38,IF($W$61,MAX(0,N(D38)),MAX(0,AA38)),0) -> 0 | AC38: =IF(V38,IF($W$61,ABS(N(E38)),ABS(N($C$32))/$W$77),0) -> 0.75 | AD38: =IF(V38,IF($W$61,ABS(N(F38)),ABS(N($C$33))/$W$77),0) -> 0.25 | AE38: =SQRT(AC38^2+AD38^2) -> 0.79056942 | AF38: =ABS(W38) -> 25 | AG38: =ABS(X38) -> 10 | AH38: =AF38>$W$69 -> TRUE | AI38: =AG38>$W$70 -> FALSE | AJ38: =SQRT(W38^2+X38^2) -> 26.925824 | AK38: =IF(AND(AH38,AI38),$W$64,AH38) -> TRUE | AL38: =IF($W$63,AG38-$W$68/2,($W$70-$W$68)-AG38) -> 9.6 | AM38: =($W$69-$W$67)-AF38 -> -6.4 | AN38: =IF($W$62,IF(AJ38>$W$65/2,AJ38-$W$65/2,$W$65/2-$W$67-AJ38),IF(OR(AH38,AI38),IF(AK38,AF38-$W$69,AG38-$W$70),MIN(AL38,AM38))) -> 5 | AO38: =IF($W$62,IF(AJ38>$W$65/2,MIN($C$17/2-AF38,$C$18/2-AG38),1.25*AN38),IF(OR(AH38,AI38),IF(AK38,$C$17/2-AF38,$C$18/2-AG38),IF(AND(AL38<=AM38,$W$63),$C$18/2-AG38,1.25*AN38))) -> 5 | AP38: =IF(V38,IF($W$62,2*PI()*MAX(AJ38,0.1)/$W$77,IF(OR(AH38,AI38),IF(AK38,$C$18/SUMPRODUCT(--($V$37:$V$48),--($W$37:$W$48=W38)),$C$17/SUMPRODUCT(--($V$37:$V$48),--($X$37:$X$48=X38))),IF(AL38<=AM38,($W$65-2*$W$67)/SUMPRODUCT(--($V$37:$V$48),--($X$37:$X$48=X38)),IF($W$63,$W$66,$W$66-2*$W$68)/SUMPRODUCT(--($V$37:$V$48),--($W$37:$W$48=W38))))),1) -> 15 | AQ38: =MAX(0.1,AN38) -> 5 | AR38: =MAX(0.1,MIN(AO38,1.25*AQ38)) -> 5 | AS38: =AP38*$C$19^4/(AR38*AQ38^2*$W$78) -> 5.5717833 | AT38: =IF(AND(V38,NOT($W$61),AB38>0),MAX(0,AB38*(0.5-AS38/30)/((3*AR38/(4*AQ38)+1)*(AR38/(3*AQ38)+1)+AS38/6)),0) -> 0 | AU38: =AB38+AT38 -> 0 | AV38: =IF(AB38>0,MAX(AB38*AQ38-AT38*AR38,AT38*AR38)/AP38,0) -> 0 | AW38: =$C$23/2-AF38 -> 15 | AX38: =$C$24/2-AG38 -> 20 | AY38: =IF(V38,MIN(AW38,AX38),"") -> 15 | BC38: =IF(AND(V38,V39),SQRT((W38-W39)^2+(X38-X39)^2),"") -> 20 | BD38: =IF(AND(V38,V40),SQRT((W38-W40)^2+(X38-X40)^2),"") -> 53.851648 | BE38: =IF(AND(V38,V41),SQRT((W38-W41)^2+(X38-X41)^2),"") | BF38: =IF(AND(V38,V42),SQRT((W38-W42)^2+(X38-X42)^2),"") | BG38: =IF(AND(V38,V43),SQRT((W38-W43)^2+(X38-X43)^2),"") | BH38: =IF(AND(V38,V44),SQRT((W38-W44)^2+(X38-X44)^2),"") | BI38: =IF(AND(V38,V45),SQRT((W38-W45)^2+(X38-X45)^2),"") | BJ38: =IF(AND(V38,V46),SQRT((W38-W46)^2+(X38-X46)^2),"") | BK38: =IF(AND(V38,V47),SQRT((W38-W47)^2+(X38-X47)^2),"") | BL38: =IF(AND(V38,V48),SQRT((W38-W48)^2+(X38-X48)^2),"") | BM38: =IF(V38,AND(AF38<=$C$17/2-1.5*'2-Anchor Bolt'!$C$12/10,AG38<=$C$18/2-1.5*'2-Anchor Bolt'!$C$12/10),TRUE) -> TRUE | BP38: =1*$C$23/2/$W$126 -> 0.83333333 | BQ38: =-1*$C$24/2/$W$126 -> -0.625 | BR38: =1*$C$17/2/$W$126 -> 0.625 | BS38: =-1*$C$18/2/$W$126 -> -0.3125 | BT38: =IF($W$62,$W$69*COS((2*PI()*1/36)),IF($W$63,(-1*$W$69+(1)*$W$67),1*$W$69))/$W$126 -> -0.3875 | BU38: =IF($W$62,$W$69*SIN((2*PI()*1/36)),IF($W$63,(-1*$W$70),-1*$W$70))/$W$126 -> -0.20833333 | BV38: =IF($W$62,($W$69-$W$67)*COS((2*PI()*1/36)),IF($W$63,-$W$69,1*($W$69-$W$67)))/$W$126 -> -0.41666667 | BW38: =IF($W$62,($W$69-$W$67)*SIN((2*PI()*1/36)),IF($W$63,-$W$70,-1*($W$70-$W$68)))/$W$126 -> -0.20833333 | BX38: =($C$23/2+5)/$W$126 -> 0.9375 | BY38: 0 | CH38: =IF(AND($W$88="C",ISNUMBER($W$127)),IF($W$64,$W$127,1*$C$17/2*1.1),NA())/$W$126 -> 0.077231367 | CI38: =IF(AND($W$88="C",ISNUMBER($W$127)),IF($W$64,1*$C$18/2*1.1,$W$127),NA())/$W$126 -> 0.34375 | CJ38: =IF(OR($W$88="A",AND($W$88="C",ISNUMBER($W$127))),IF($W$64,IF($W$88="A",-$W$75*$W$71/2,$W$127),(-$W$72/2+$W$72*1/20)),NA())/$W$126 -> 0.077231367 | CK38: =IF(OR($W$88="A",AND($W$88="C",ISNUMBER($W$127))),IF($W$64,(-$W$72/2+$W$72*1/20),IF($W$88="A",-$W$75*$W$71/2,$W$127)),NA())/$W$126 -> -0.28125 | CL38: =IF(V38,W38/$W$126,NA()) -> 0.52083333 | CM38: =IF(V38,X38/$W$126,NA()) -> -0.20833333 | CN38: =IF(V38,"("&TEXT(W38,"0.0")&" , "&TEXT(X38,"0.0")&")","") -> (25.0 , -10.0) | CO38: 0 | CP38: =($C$24/2+5)/$W$126 -> 0.72916667 | CQ38: Y
A39: 3 | B39: 25 | C39: 10 | V39: =AND(ISNUMBER(B39),ISNUMBER(C39)) -> TRUE | W39: =IF(V39,B39,0) -> 25 | X39: =IF(V39,C39,0) -> 10 | Y39: =IF($W$64,W39,X39) -> 25 | Z39: =IF(V39,$W$71/2-$W$75*Y39,-1) -> 5 | AA39: =IF(V39,IF($W$88="B",$W$86+$W$85*(Z39-$W$82),IF($W$88="C",$W$93*$W$81*MAX(Z39-$W$90,0),0)),0) -> 0 | AB39: =IF(V39,IF($W$61,MAX(0,N(D39)),MAX(0,AA39)),0) -> 0 | AC39: =IF(V39,IF($W$61,ABS(N(E39)),ABS(N($C$32))/$W$77),0) -> 0.75 | AD39: =IF(V39,IF($W$61,ABS(N(F39)),ABS(N($C$33))/$W$77),0) -> 0.25 | AE39: =SQRT(AC39^2+AD39^2) -> 0.79056942 | AF39: =ABS(W39) -> 25 | AG39: =ABS(X39) -> 10 | AH39: =AF39>$W$69 -> TRUE | AI39: =AG39>$W$70 -> FALSE | AJ39: =SQRT(W39^2+X39^2) -> 26.925824 | AK39: =IF(AND(AH39,AI39),$W$64,AH39) -> TRUE | AL39: =IF($W$63,AG39-$W$68/2,($W$70-$W$68)-AG39) -> 9.6 | AM39: =($W$69-$W$67)-AF39 -> -6.4 | AN39: =IF($W$62,IF(AJ39>$W$65/2,AJ39-$W$65/2,$W$65/2-$W$67-AJ39),IF(OR(AH39,AI39),IF(AK39,AF39-$W$69,AG39-$W$70),MIN(AL39,AM39))) -> 5 | AO39: =IF($W$62,IF(AJ39>$W$65/2,MIN($C$17/2-AF39,$C$18/2-AG39),1.25*AN39),IF(OR(AH39,AI39),IF(AK39,$C$17/2-AF39,$C$18/2-AG39),IF(AND(AL39<=AM39,$W$63),$C$18/2-AG39,1.25*AN39))) -> 5 | AP39: =IF(V39,IF($W$62,2*PI()*MAX(AJ39,0.1)/$W$77,IF(OR(AH39,AI39),IF(AK39,$C$18/SUMPRODUCT(--($V$37:$V$48),--($W$37:$W$48=W39)),$C$17/SUMPRODUCT(--($V$37:$V$48),--($X$37:$X$48=X39))),IF(AL39<=AM39,($W$65-2*$W$67)/SUMPRODUCT(--($V$37:$V$48),--($X$37:$X$48=X39)),IF($W$63,$W$66,$W$66-2*$W$68)/SUMPRODUCT(--($V$37:$V$48),--($W$37:$W$48=W39))))),1) -> 15 | AQ39: =MAX(0.1,AN39) -> 5 | AR39: =MAX(0.1,MIN(AO39,1.25*AQ39)) -> 5 | AS39: =AP39*$C$19^4/(AR39*AQ39^2*$W$78) -> 5.5717833 | AT39: =IF(AND(V39,NOT($W$61),AB39>0),MAX(0,AB39*(0.5-AS39/30)/((3*AR39/(4*AQ39)+1)*(AR39/(3*AQ39)+1)+AS39/6)),0) -> 0 | AU39: =AB39+AT39 -> 0 | AV39: =IF(AB39>0,MAX(AB39*AQ39-AT39*AR39,AT39*AR39)/AP39,0) -> 0 | AW39: =$C$23/2-AF39 -> 15 | AX39: =$C$24/2-AG39 -> 20 | AY39: =IF(V39,MIN(AW39,AX39),"") -> 15 | BD39: =IF(AND(V39,V40),SQRT((W39-W40)^2+(X39-X40)^2),"") -> 50 | BE39: =IF(AND(V39,V41),SQRT((W39-W41)^2+(X39-X41)^2),"") | BF39: =IF(AND(V39,V42),SQRT((W39-W42)^2+(X39-X42)^2),"") | BG39: =IF(AND(V39,V43),SQRT((W39-W43)^2+(X39-X43)^2),"") | BH39: =IF(AND(V39,V44),SQRT((W39-W44)^2+(X39-X44)^2),"") | BI39: =IF(AND(V39,V45),SQRT((W39-W45)^2+(X39-X45)^2),"") | BJ39: =IF(AND(V39,V46),SQRT((W39-W46)^2+(X39-X46)^2),"") | BK39: =IF(AND(V39,V47),SQRT((W39-W47)^2+(X39-X47)^2),"") | BL39: =IF(AND(V39,V48),SQRT((W39-W48)^2+(X39-X48)^2),"") | BM39: =IF(V39,AND(AF39<=$C$17/2-1.5*'2-Anchor Bolt'!$C$12/10,AG39<=$C$18/2-1.5*'2-Anchor Bolt'!$C$12/10),TRUE) -> TRUE | BP39: =1*$C$23/2/$W$126 -> 0.83333333 | BQ39: =1*$C$24/2/$W$126 -> 0.625 | BR39: =1*$C$17/2/$W$126 -> 0.625 | BS39: =1*$C$18/2/$W$126 -> 0.3125 | BT39: =IF($W$62,$W$69*COS((2*PI()*2/36)),IF($W$63,(-1*$W$69+(1)*$W$67),1*$W$69))/$W$126 -> -0.3875 | BU39: =IF($W$62,$W$69*SIN((2*PI()*2/36)),IF($W$63,((-1)*$W$68/2),1*$W$70))/$W$126 -> -0.0083333333 | BV39: =IF($W$62,($W$69-$W$67)*COS((2*PI()*2/36)),IF($W$63,-$W$69,1*($W$69-$W$67)))/$W$126 -> -0.41666667 | BW39: =IF($W$62,($W$69-$W$67)*SIN((2*PI()*2/36)),IF($W$63,-$W$70,1*($W$70-$W$68)))/$W$126 -> -0.20833333 | BX39: 0 | BY39: =-($C$24/2+5)/$W$126 -> -0.72916667 | CJ39: =IF(OR($W$88="A",AND($W$88="C",ISNUMBER($W$127))),IF($W$64,$W$75*$W$71/2,(-$W$72/2+$W$72*2/20)),NA())/$W$126 -> 0.625 | CK39: =IF(OR($W$88="A",AND($W$88="C",ISNUMBER($W$127))),IF($W$64,(-$W$72/2+$W$72*2/20),$W$75*$W$71/2),NA())/$W$126 -> -0.25 | CL39: =IF(V39,W39/$W$126,NA()) -> 0.52083333 | CM39: =IF(V39,X39/$W$126,NA()) -> 0.20833333 | CN39: =IF(V39,"("&TEXT(W39,"0.0")&" , "&TEXT(X39,"0.0")&")","") -> (25.0 , 10.0) | CO39: 0 | CP39: =-($C$24/2+1)/$W$126 -> -0.64583333 | CQ39: ="Bx = "&$C$23&" cm" -> Bx = 80 cm
A40: 4 | B40: -25 | C40: 10 | V40: =AND(ISNUMBER(B40),ISNUMBER(C40)) -> TRUE | W40: =IF(V40,B40,0) -> -25 | X40: =IF(V40,C40,0) -> 10 | Y40: =IF($W$64,W40,X40) -> -25 | Z40: =IF(V40,$W$71/2-$W$75*Y40,-1) -> 55 | AA40: =IF(V40,IF($W$88="B",$W$86+$W$85*(Z40-$W$82),IF($W$88="C",$W$93*$W$81*MAX(Z40-$W$90,0),0)),0) -> 4.0587297 | AB40: =IF(V40,IF($W$61,MAX(0,N(D40)),MAX(0,AA40)),0) -> 4.0587297 | AC40: =IF(V40,IF($W$61,ABS(N(E40)),ABS(N($C$32))/$W$77),0) -> 0.75 | AD40: =IF(V40,IF($W$61,ABS(N(F40)),ABS(N($C$33))/$W$77),0) -> 0.25 | AE40: =SQRT(AC40^2+AD40^2) -> 0.79056942 | AF40: =ABS(W40) -> 25 | AG40: =ABS(X40) -> 10 | AH40: =AF40>$W$69 -> TRUE | AI40: =AG40>$W$70 -> FALSE | AJ40: =SQRT(W40^2+X40^2) -> 26.925824 | AK40: =IF(AND(AH40,AI40),$W$64,AH40) -> TRUE | AL40: =IF($W$63,AG40-$W$68/2,($W$70-$W$68)-AG40) -> 9.6 | AM40: =($W$69-$W$67)-AF40 -> -6.4 | AN40: =IF($W$62,IF(AJ40>$W$65/2,AJ40-$W$65/2,$W$65/2-$W$67-AJ40),IF(OR(AH40,AI40),IF(AK40,AF40-$W$69,AG40-$W$70),MIN(AL40,AM40))) -> 5 | AO40: =IF($W$62,IF(AJ40>$W$65/2,MIN($C$17/2-AF40,$C$18/2-AG40),1.25*AN40),IF(OR(AH40,AI40),IF(AK40,$C$17/2-AF40,$C$18/2-AG40),IF(AND(AL40<=AM40,$W$63),$C$18/2-AG40,1.25*AN40))) -> 5 | AP40: =IF(V40,IF($W$62,2*PI()*MAX(AJ40,0.1)/$W$77,IF(OR(AH40,AI40),IF(AK40,$C$18/SUMPRODUCT(--($V$37:$V$48),--($W$37:$W$48=W40)),$C$17/SUMPRODUCT(--($V$37:$V$48),--($X$37:$X$48=X40))),IF(AL40<=AM40,($W$65-2*$W$67)/SUMPRODUCT(--($V$37:$V$48),--($X$37:$X$48=X40)),IF($W$63,$W$66,$W$66-2*$W$68)/SUMPRODUCT(--($V$37:$V$48),--($W$37:$W$48=W40))))),1) -> 15 | AQ40: =MAX(0.1,AN40) -> 5 | AR40: =MAX(0.1,MIN(AO40,1.25*AQ40)) -> 5 | AS40: =AP40*$C$19^4/(AR40*AQ40^2*$W$78) -> 5.5717833 | AT40: =IF(AND(V40,NOT($W$61),AB40>0),MAX(0,AB40*(0.5-AS40/30)/((3*AR40/(4*AQ40)+1)*(AR40/(3*AQ40)+1)+AS40/6)),0) -> 0.39103829 | AU40: =AB40+AT40 -> 4.449768 | AV40: =IF(AB40>0,MAX(AB40*AQ40-AT40*AR40,AT40*AR40)/AP40,0) -> 1.2225638 | AW40: =$C$23/2-AF40 -> 15 | AX40: =$C$24/2-AG40 -> 20 | AY40: =IF(V40,MIN(AW40,AX40),"") -> 15 | BE40: =IF(AND(V40,V41),SQRT((W40-W41)^2+(X40-X41)^2),"") | BF40: =IF(AND(V40,V42),SQRT((W40-W42)^2+(X40-X42)^2),"") | BG40: =IF(AND(V40,V43),SQRT((W40-W43)^2+(X40-X43)^2),"") | BH40: =IF(AND(V40,V44),SQRT((W40-W44)^2+(X40-X44)^2),"") | BI40: =IF(AND(V40,V45),SQRT((W40-W45)^2+(X40-X45)^2),"") | BJ40: =IF(AND(V40,V46),SQRT((W40-W46)^2+(X40-X46)^2),"") | BK40: =IF(AND(V40,V47),SQRT((W40-W47)^2+(X40-X47)^2),"") | BL40: =IF(AND(V40,V48),SQRT((W40-W48)^2+(X40-X48)^2),"") | BM40: =IF(V40,AND(AF40<=$C$17/2-1.5*'2-Anchor Bolt'!$C$12/10,AG40<=$C$18/2-1.5*'2-Anchor Bolt'!$C$12/10),TRUE) -> TRUE | BP40: =-1*$C$23/2/$W$126 -> -0.83333333 | BQ40: =1*$C$24/2/$W$126 -> 0.625 | BR40: =-1*$C$17/2/$W$126 -> -0.625 | BS40: =1*$C$18/2/$W$126 -> 0.3125 | BT40: =IF($W$62,$W$69*COS((2*PI()*3/36)),IF($W$63,(1*$W$69+(-1)*$W$67),-1*$W$69))/$W$126 -> 0.3875 | BU40: =IF($W$62,$W$69*SIN((2*PI()*3/36)),IF($W$63,((-1)*$W$68/2),1*$W$70))/$W$126 -> -0.0083333333 | BV40: =IF($W$62,($W$69-$W$67)*COS((2*PI()*3/36)),IF($W$63,-$W$69,-1*($W$69-$W$67)))/$W$126 -> -0.41666667 | BW40: =IF($W$62,($W$69-$W$67)*SIN((2*PI()*3/36)),IF($W$63,-$W$70,1*($W$70-$W$68)))/$W$126 -> -0.20833333 | BX40: 0 | BY40: =($C$24/2+5)/$W$126 -> 0.72916667 | CJ40: =IF(OR($W$88="A",AND($W$88="C",ISNUMBER($W$127))),IF($W$64,IF($W$88="A",-$W$75*$W$71/2,$W$127),(-$W$72/2+$W$72*3/20)),NA())/$W$126 -> 0.077231367 | CK40: =IF(OR($W$88="A",AND($W$88="C",ISNUMBER($W$127))),IF($W$64,(-$W$72/2+$W$72*3/20),IF($W$88="A",-$W$75*$W$71/2,$W$127)),NA())/$W$126 -> -0.21875 | CL40: =IF(V40,W40/$W$126,NA()) -> -0.52083333 | CM40: =IF(V40,X40/$W$126,NA()) -> 0.20833333 | CN40: =IF(V40,"("&TEXT(W40,"0.0")&" , "&TEXT(X40,"0.0")&")","") -> (-25.0 , 10.0) | CO40: =-($C$23/2+1)/$W$126 -> -0.85416667 | CP40: 0 | CQ40: ="By = "&$C$24 -> By = 60
A41: 5 | V41: =AND(ISNUMBER(B41),ISNUMBER(C41)) -> FALSE | W41: =IF(V41,B41,0) -> 0 | X41: =IF(V41,C41,0) -> 0 | Y41: =IF($W$64,W41,X41) -> 0 | Z41: =IF(V41,$W$71/2-$W$75*Y41,-1) -> -1 | AA41: =IF(V41,IF($W$88="B",$W$86+$W$85*(Z41-$W$82),IF($W$88="C",$W$93*$W$81*MAX(Z41-$W$90,0),0)),0) -> 0 | AB41: =IF(V41,IF($W$61,MAX(0,N(D41)),MAX(0,AA41)),0) -> 0 | AC41: =IF(V41,IF($W$61,ABS(N(E41)),ABS(N($C$32))/$W$77),0) -> 0 | AD41: =IF(V41,IF($W$61,ABS(N(F41)),ABS(N($C$33))/$W$77),0) -> 0 | AE41: =SQRT(AC41^2+AD41^2) -> 0 | AF41: =ABS(W41) -> 0 | AG41: =ABS(X41) -> 0 | AH41: =AF41>$W$69 -> FALSE | AI41: =AG41>$W$70 -> FALSE | AJ41: =SQRT(W41^2+X41^2) -> 0 | AK41: =IF(AND(AH41,AI41),$W$64,AH41) -> FALSE | AL41: =IF($W$63,AG41-$W$68/2,($W$70-$W$68)-AG41) -> -0.4 | AM41: =($W$69-$W$67)-AF41 -> 18.6 | AN41: =IF($W$62,IF(AJ41>$W$65/2,AJ41-$W$65/2,$W$65/2-$W$67-AJ41),IF(OR(AH41,AI41),IF(AK41,AF41-$W$69,AG41-$W$70),MIN(AL41,AM41))) -> -0.4 | AO41: =IF($W$62,IF(AJ41>$W$65/2,MIN($C$17/2-AF41,$C$18/2-AG41),1.25*AN41),IF(OR(AH41,AI41),IF(AK41,$C$17/2-AF41,$C$18/2-AG41),IF(AND(AL41<=AM41,$W$63),$C$18/2-AG41,1.25*AN41))) -> 15 | AP41: =IF(V41,IF($W$62,2*PI()*MAX(AJ41,0.1)/$W$77,IF(OR(AH41,AI41),IF(AK41,$C$18/SUMPRODUCT(--($V$37:$V$48),--($W$37:$W$48=W41)),$C$17/SUMPRODUCT(--($V$37:$V$48),--($X$37:$X$48=X41))),IF(AL41<=AM41,($W$65-2*$W$67)/SUMPRODUCT(--($V$37:$V$48),--($X$37:$X$48=X41)),IF($W$63,$W$66,$W$66-2*$W$68)/SUMPRODUCT(--($V$37:$V$48),--($W$37:$W$48=W41))))),1) -> 1 | AQ41: =MAX(0.1,AN41) -> 0.1 | AR41: =MAX(0.1,MIN(AO41,1.25*AQ41)) -> 0.125 | AS41: =AP41*$C$19^4/(AR41*AQ41^2*$W$78) -> 37145.222 | AT41: =IF(AND(V41,NOT($W$61),AB41>0),MAX(0,AB41*(0.5-AS41/30)/((3*AR41/(4*AQ41)+1)*(AR41/(3*AQ41)+1)+AS41/6)),0) -> 0 | AU41: =AB41+AT41 -> 0 | AV41: =IF(AB41>0,MAX(AB41*AQ41-AT41*AR41,AT41*AR41)/AP41,0) -> 0 | AW41: =$C$23/2-AF41 -> 40 | AX41: =$C$24/2-AG41 -> 30 | AY41: =IF(V41,MIN(AW41,AX41),"") | BF41: =IF(AND(V41,V42),SQRT((W41-W42)^2+(X41-X42)^2),"") | BG41: =IF(AND(V41,V43),SQRT((W41-W43)^2+(X41-X43)^2),"") | BH41: =IF(AND(V41,V44),SQRT((W41-W44)^2+(X41-X44)^2),"") | BI41: =IF(AND(V41,V45),SQRT((W41-W45)^2+(X41-X45)^2),"") | BJ41: =IF(AND(V41,V46),SQRT((W41-W46)^2+(X41-X46)^2),"") | BK41: =IF(AND(V41,V47),SQRT((W41-W47)^2+(X41-X47)^2),"") | BL41: =IF(AND(V41,V48),SQRT((W41-W48)^2+(X41-X48)^2),"") | BM41: =IF(V41,AND(AF41<=$C$17/2-1.5*'2-Anchor Bolt'!$C$12/10,AG41<=$C$18/2-1.5*'2-Anchor Bolt'!$C$12/10),TRUE) -> TRUE | BP41: =-1*$C$23/2/$W$126 -> -0.83333333 | BQ41: =-1*$C$24/2/$W$126 -> -0.625 | BR41: =-1*$C$17/2/$W$126 -> -0.625 | BS41: =-1*$C$18/2/$W$126 -> -0.3125 | BT41: =IF($W$62,$W$69*COS((2*PI()*4/36)),IF($W$63,(1*$W$69+(-1)*$W$67),-1*$W$69))/$W$126 -> 0.3875 | BU41: =IF($W$62,$W$69*SIN((2*PI()*4/36)),IF($W$63,(-1*$W$70),-1*$W$70))/$W$126 -> -0.20833333 | BV41: =IF($W$62,($W$69-$W$67)*COS((2*PI()*4/36)),IF($W$63,-$W$69,-1*($W$69-$W$67)))/$W$126 -> -0.41666667 | BW41: =IF($W$62,($W$69-$W$67)*SIN((2*PI()*4/36)),IF($W$63,-$W$70,-1*($W$70-$W$68)))/$W$126 -> -0.20833333 | CJ41: =IF(OR($W$88="A",AND($W$88="C",ISNUMBER($W$127))),IF($W$64,$W$75*$W$71/2,(-$W$72/2+$W$72*4/20)),NA())/$W$126 -> 0.625 | CK41: =IF(OR($W$88="A",AND($W$88="C",ISNUMBER($W$127))),IF($W$64,(-$W$72/2+$W$72*4/20),$W$75*$W$71/2),NA())/$W$126 -> -0.1875 | CL41: =IF(V41,W41/$W$126,NA()) -> #N/A | CM41: =IF(V41,X41/$W$126,NA()) -> #N/A | CN41: =IF(V41,"("&TEXT(W41,"0.0")&" , "&TEXT(X41,"0.0")&")","") | CO41: =IF(AND($W$88="C",ISNUMBER($W$127)),IF($W$64,$W$127,$C$17/2*1.1),0)/$W$126 -> 0.077231367 | CP41: =IF(AND($W$88="C",ISNUMBER($W$127)),IF($W$64,$C$18/2*1.1,$W$127),0)/$W$126 -> 0.34375 | CQ41: =IF(AND($W$88="C",ISNUMBER($W$127)),"N.A.","") -> N.A.
A42: 6 | V42: =AND(ISNUMBER(B42),ISNUMBER(C42)) -> FALSE | W42: =IF(V42,B42,0) -> 0 | X42: =IF(V42,C42,0) -> 0 | Y42: =IF($W$64,W42,X42) -> 0 | Z42: =IF(V42,$W$71/2-$W$75*Y42,-1) -> -1 | AA42: =IF(V42,IF($W$88="B",$W$86+$W$85*(Z42-$W$82),IF($W$88="C",$W$93*$W$81*MAX(Z42-$W$90,0),0)),0) -> 0 | AB42: =IF(V42,IF($W$61,MAX(0,N(D42)),MAX(0,AA42)),0) -> 0 | AC42: =IF(V42,IF($W$61,ABS(N(E42)),ABS(N($C$32))/$W$77),0) -> 0 | AD42: =IF(V42,IF($W$61,ABS(N(F42)),ABS(N($C$33))/$W$77),0) -> 0 | AE42: =SQRT(AC42^2+AD42^2) -> 0 | AF42: =ABS(W42) -> 0 | AG42: =ABS(X42) -> 0 | AH42: =AF42>$W$69 -> FALSE | AI42: =AG42>$W$70 -> FALSE | AJ42: =SQRT(W42^2+X42^2) -> 0 | AK42: =IF(AND(AH42,AI42),$W$64,AH42) -> FALSE | AL42: =IF($W$63,AG42-$W$68/2,($W$70-$W$68)-AG42) -> -0.4 | AM42: =($W$69-$W$67)-AF42 -> 18.6 | AN42: =IF($W$62,IF(AJ42>$W$65/2,AJ42-$W$65/2,$W$65/2-$W$67-AJ42),IF(OR(AH42,AI42),IF(AK42,AF42-$W$69,AG42-$W$70),MIN(AL42,AM42))) -> -0.4 | AO42: =IF($W$62,IF(AJ42>$W$65/2,MIN($C$17/2-AF42,$C$18/2-AG42),1.25*AN42),IF(OR(AH42,AI42),IF(AK42,$C$17/2-AF42,$C$18/2-AG42),IF(AND(AL42<=AM42,$W$63),$C$18/2-AG42,1.25*AN42))) -> 15 | AP42: =IF(V42,IF($W$62,2*PI()*MAX(AJ42,0.1)/$W$77,IF(OR(AH42,AI42),IF(AK42,$C$18/SUMPRODUCT(--($V$37:$V$48),--($W$37:$W$48=W42)),$C$17/SUMPRODUCT(--($V$37:$V$48),--($X$37:$X$48=X42))),IF(AL42<=AM42,($W$65-2*$W$67)/SUMPRODUCT(--($V$37:$V$48),--($X$37:$X$48=X42)),IF($W$63,$W$66,$W$66-2*$W$68)/SUMPRODUCT(--($V$37:$V$48),--($W$37:$W$48=W42))))),1) -> 1 | AQ42: =MAX(0.1,AN42) -> 0.1 | AR42: =MAX(0.1,MIN(AO42,1.25*AQ42)) -> 0.125 | AS42: =AP42*$C$19^4/(AR42*AQ42^2*$W$78) -> 37145.222 | AT42: =IF(AND(V42,NOT($W$61),AB42>0),MAX(0,AB42*(0.5-AS42/30)/((3*AR42/(4*AQ42)+1)*(AR42/(3*AQ42)+1)+AS42/6)),0) -> 0 | AU42: =AB42+AT42 -> 0 | AV42: =IF(AB42>0,MAX(AB42*AQ42-AT42*AR42,AT42*AR42)/AP42,0) -> 0 | AW42: =$C$23/2-AF42 -> 40 | AX42: =$C$24/2-AG42 -> 30 | AY42: =IF(V42,MIN(AW42,AX42),"") | BG42: =IF(AND(V42,V43),SQRT((W42-W43)^2+(X42-X43)^2),"") | BH42: =IF(AND(V42,V44),SQRT((W42-W44)^2+(X42-X44)^2),"") | BI42: =IF(AND(V42,V45),SQRT((W42-W45)^2+(X42-X45)^2),"") | BJ42: =IF(AND(V42,V46),SQRT((W42-W46)^2+(X42-X46)^2),"") | BK42: =IF(AND(V42,V47),SQRT((W42-W47)^2+(X42-X47)^2),"") | BL42: =IF(AND(V42,V48),SQRT((W42-W48)^2+(X42-X48)^2),"") | BM42: =IF(V42,AND(AF42<=$C$17/2-1.5*'2-Anchor Bolt'!$C$12/10,AG42<=$C$18/2-1.5*'2-Anchor Bolt'!$C$12/10),TRUE) -> TRUE | BT42: =IF($W$62,$W$69*COS((2*PI()*5/36)),IF($W$63,(1*$W$69+(0)*$W$67),-1*$W$69))/$W$126 -> 0.41666667 | BU42: =IF($W$62,$W$69*SIN((2*PI()*5/36)),IF($W$63,(-1*$W$70),-1*$W$70))/$W$126 -> -0.20833333 | BV42: =IF($W$62,($W$69-$W$67)*COS((2*PI()*5/36)),IF($W$63,-$W$69,-1*($W$69-$W$67)))/$W$126 -> -0.41666667 | BW42: =IF($W$62,($W$69-$W$67)*SIN((2*PI()*5/36)),IF($W$63,-$W$70,-1*($W$70-$W$68)))/$W$126 -> -0.20833333 | CJ42: =IF(OR($W$88="A",AND($W$88="C",ISNUMBER($W$127))),IF($W$64,IF($W$88="A",-$W$75*$W$71/2,$W$127),(-$W$72/2+$W$72*5/20)),NA())/$W$126 -> 0.077231367 | CK42: =IF(OR($W$88="A",AND($W$88="C",ISNUMBER($W$127))),IF($W$64,(-$W$72/2+$W$72*5/20),IF($W$88="A",-$W$75*$W$71/2,$W$127)),NA())/$W$126 -> -0.15625 | CL42: =IF(V42,W42/$W$126,NA()) -> #N/A | CM42: =IF(V42,X42/$W$126,NA()) -> #N/A | CN42: =IF(V42,"("&TEXT(W42,"0.0")&" , "&TEXT(X42,"0.0")&")","")
...

Sheet 2-Anchor Bolt
A1: MOHAMED MUSTAFA | Steel Structures Design | L1: DESIGN BY : | M1: ENG. Mohamed Mustafa | P1: REV. NO. : | Q1: 3 | R1: DATE OF REV : | T1: 45940
A2: Anchor Bolt & Washer Plate Design - ECP 205 (ASD / LRFD) | L2: Phone | M2: ="01140949980" -> 01140949980 | P2: WhatsApp
A3: DESIGN BY : | B3: ENG. Mohamed Mustafa | L3: Linkedin account | P3: Facebook account
A4: Project ID. : | L4: Portfolio
A6: Data Entry
G7: =C12 -> 30 | K7: angle in rad = | M7: =1/(C12/20) -> 0.66666667 | P7: =1*M9 -> 0.10301128 | Q7: "@1cm width"
A8: Design Method : | C8: ='1-Base Plate'!C8 -> ASD | D8: Anchor Shape : | F8: Straight | K8: Perimeter @ r2 washer = | N8: =M7*(C15/2) -> 2.6666667 | P8: =N8*M9 -> 0.27469676 | Q8: ="@"&N8&"cmwidth" -> @2.66666666666667cmwidth
A9: Bolt Properties : | C9: ST 52 | K9: stress in washer = | M9: =E34/B32 -> 0.10301128 | P9: center1 = | Q9: =(C15/2-C12/20)/2 -> 1.25 | R9: cm
A10: Force in bolt = | C10: ='1-Base Plate'!$W$123 -> 4.449768 | D10: ton | K10: area hatched = | M10: =B32*(0.5*M7/PI()) -> 4.5833333 | N10: cm2 | P10: Center2 = | Q10: =(2/3)*(C15/2-C12/10/2) -> 1.6666667 | R10: cm | T10: G | U10: 4 | V10: 0.6
A11: Embedment hef = | C11: 120 | D11: cm | K11: W in Circular strip | M11: =M10*M9 -> 0.47213505
A12: Bolt Diameter = | C12: 30 | D12: mm | K12: Moment 1 = | L12: =P7*(Q9*2)*(Q9) -> 0.32191026 | M12: t.cm | R12: =IF(F8="Straight",1,0.75) -> 1
A13: Concrete Fcu = | C13: ='1-Base Plate'!C22 -> 250 | D13: kg/cm2 | K13: Moment 2 = | L13: =Q9*(P8-P7)*(Q10) -> 0.35767807 | M13: t.cm | P13: =P7*Q9*2+0.5*(P8-P7)*Q9*2 -> 0.47213505 | R13: =IF(F15="Plain",1,0.75) -> 1
A14: Consider Bond : | C14: No | K14: Mt = | L14: =(L13+L12) -> 0.67958833 | M14: t.cm
A15: Washer Diameter = | C15: =CEILING(MAX($T$23,$T$24),1) -> 8 | D15: cm | E15: Anchor type: | F15: Plain | L15: =E34/(2*PI()) -> 0.70820258
A16: Washer Properties : | C16: ST 37
A17: Selected Thickness = | C17: =IFERROR(INDEX($U$20:$U$31,COUNTIF($U$20:$U$31,"<"&MAX(C40,1))+1),"> 6") -> 1.6 | D17: cm | E17: =IF(C10<=0,"No tension",IF(AND(F25="Safe",F42="Safe",F45="Safe",F48="Safe",F50="Safe",F51="Safe",F53="Safe"),"Safe","Check design steps")) -> Safe | N17: =P7*(Q9*2)*(Q9) -> 0.32191026
B18: =IF(C10<=0,"No tension in the bolts (sheet 1) - washer plate not needed","") | N18: =Q9*(P8-P7)*(Q10) -> 0.35767807
A19: Data Output: | S19: Helpers | U19: Std t (cm)
S20: A2 (cm2) | T20: =IF('1-Base Plate'!$W$77>1,MIN(2*'1-Base Plate'!$W$121,N('1-Base Plate'!$W$122)),2*'1-Base Plate'!$W$121)^2 -> 400 | U20: 1
A21: Bolt Properties: | Q21: =N8&"cm" -> 2.66666666666667cm | S21: fb0 (kg/cm2) | T21: =$C$27 -> 70 | U21: 1.2
A22: Fy = | B22: =IF(C9="ST 37",2.4, IF(C9="ST 44",2.8, IF(C9="ST 52",3.6, IF(C9="G4.6",2.4, IF(C9="G4.8",3.2, IF(C9="G5.6",3, IF(C9="G5.8",4, IF(C9="G6.8",4.8, IF(C9="G8.8",6.4,IF(C9="G10.9",9,"")))))))))) -> 3.6 | C22: t/cm2 | D22: Fu = | E22: =IF(C9="ST 37",3.6, IF(C9="ST 44",4.4, IF(C9="ST 52",5.2, IF(C9="G4.6",4, IF(C9="G4.8",4, IF(C9="G5.6",5, IF(C9="G5.8",5, IF(C9="G6.8",6, IF(C9="G8.8",8,IF(C9="G10.9",10,"")))))))))) -> 5.2 | F22: t/cm2 | L22: =C15/2&"cm" -> 4cm | S22: A1 req (cm2) | T22: =MAX($C$34/(2*$T$21),($C$34/$T$21)^2/$T$20) -> 31.784057 | U22: 1.5
A23: Bolt Area = | B23: =PI()*((C12/10)/2)^2 -> 7.0685835 | C23: cm2 | D23: Perimeter = | E23: =PI()*C12/10 -> 9.424778 | F23: cm | G23: =C11&"cm" -> 120cm | S23: D bearing (cm) | T23: =SQRT(4*($T$22+$B$23)/PI()) -> 7.0334002 | U23: 1.6
A24: Bond Surface Area = | C24: =E23*C11 -> 1130.9734 | D24: cm2 | Q24: ="Area Hatched = "&M10&" cm" -> Area Hatched = 4.58333333333333 cm | S24: D min = 2.5d (cm) | T24: =2.5*$C$12/10 -> 7.5 | U24: 2
A25: Bolt Allowable tension = | C25: =IF(C8="ASD",0.33*0.78*B23*E22,0.75*0.78*B23*E22) -> 9.4611576 | D25: =IF(C25>=C10,"> ","< ")&TEXT(C10,"0.00") -> > 4.45 | F25: =IF(C10<C25,"Safe","Un-Safe") -> Safe | U25: 2.5
A26: Concrete Properties: | U26: 3
A27: Allowable Bearing = | C27: =IF(C8="ASD",IF(C13=350,110,70),0.67*C13/1.5) -> 70 | D27: kg/cm2 | E27: ="C"&C13/10 -> C25 | U27: 3.5
A28: Concrete bond = | C28: =IF(C8="ASD",1/1.5,1/1.2)*0.3*SQRT(C13/10.2/1.5)*10.2/(R12*R13) -> 8.2462113 | D28: kg/cm2 | E28: =C8 -> ASD | U28: 4
A29: Bearing x √(A2/A1) = | C29: =MIN(2,SQRT(T20/B32)) -> 2 | D29: Allow = | E29: =C27*C29 -> 140 | F29: kg/cm2 | U29: 4.5
A30: Washer Properties: | U30: 5
A31: Fy = | B31: =IF(C16="ST 37",2.4,IF(C16="ST 44",2.8,3.6)) -> 2.4 | C31: t/cm2 | D31: Fu = | E31: =IF(C16="ST 37",3.6,IF(C16="ST 44",4.4,5.2)) -> 3.6 | F31: t/cm2 | U31: 6
A32: Area = | B32: =(PI()*C15^2/4)-B23 -> 43.196899 | C32: cm2 | D32: Bearing = | E32: =IF(C8="ASD",0.9,1.35)*B31 -> 2.16 | F32: t/cm2 | I32: =C17&" cm" -> 1.6 cm
A33: Force transfer by bolt = | C33: =IF(C14="Yes",C24*C28,0) -> 0 | D33: kg | E33: =C33/1000 -> 0 | F33: ton
A34: Force in Washer = | C34: =IF(C14="Yes",MAX(C10*1000-C33,0),MAX(C10,0)*1000) -> 4449.768 | D34: kg | E34: =C34/1000 -> 4.449768 | F34: ton | K34: =E34/B32 -> 0.10301128 | P34: =C12/20&"cm" -> 1.5cm
A35: Max Moment In Washer plate = | D35: =L14 -> 0.67958833 | E35: t.cm
K36: =6*D35/(1*1^2) -> 4.07753
A37: Washer Plate design:
A38: Allowable Stress = | B38: =IF(C8="ASD",0.72*B31,0.9*1.5*B31) -> 1.728 | C38: t/cm2
A39: Washer Plate Thickness Check: | D39: t = √((6M) / (b × σ))
A40: Design Thickness = | C40: =((6*D35)/(1*B38))^0.5 -> 1.5361255 | D40: cm | E40: Diameter = | F40: =C15&"cm" -> 8cm
A41: Concrete Bearing Check:
...

Sheet 3-Pedestal
A1: MOHAMED MUSTAFA | Steel Structures Design | L1: DESIGN BY : | M1: ENG. Mohamed Mustafa | P1: REV. NO. : | Q1: 3 | R1: DATE OF REV : | T1: 45940
A2: Concrete Pedestal Design - ACI 318-19 Ch.17 (Anchorage) + ECP 203 (Section) | L2: Phone | M2: ="01140949980" -> 01140949980 | P2: WhatsApp
A3: DESIGN BY : | B3: ENG. Mohamed Mustafa | L3: Linkedin account | P3: Facebook account
A4: Project ID. : | L4: Portfolio
A6: Data Entry
A8: Pedestal : | C8: Reinforced | D8: Rebar Steel : | F8: 36/52
A9: Pedestal Height = | C9: 150 | D9: Main Bar Ø = | F9: 16 | G9: mm
A10: Clear Cover = | C10: 5 | D10: Tie Ø = | F10: 10 | G10: mm
D11: Status : | F11: =IF(AND(OR(F53="Safe",F53="N/A",F53="By Rft."),OR(F57="Safe",F57="N/A",F57="By Rft."),OR(I62="Safe",I62="N/A",I62="By Rft."),OR(I63="Safe",I63="N/A",I63="By Rft."),OR(F68="Safe",F68="N/A",F68="By Rft."),OR(F72="Safe",F72="N/A",F72="By Rft."),OR(F78="Safe",F78="N/A",F78="By Rft."),OR(F79="Safe",F79="N/A",F79="By Rft."),OR(F80="Safe",F80="N/A",F80="By Rft.")),"Safe","Check design steps") -> Safe
A13: Data From Sheets 1 & 2:
A14: Bx × By = | B14: =$W$43&" × "&$W$44 -> 80 × 60 | C14: cm | D14: f'c = 0.8fcu = | E14: =$W$46 -> 19.607843 | F14: MPa
A15: hef = | B15: =$W$47 -> 120 | C15: cm | D15: Bolt Ø = | E15: =$W$48 -> 30 | F15: mm
A16: Washer D = | B16: =$W$50 -> 8 | C16: cm | D16: Abrg = | E16: =$W$49 -> 43.196899 | F16: cm2
A17: N = | B17: =IF($W$41,"-",ABS('1-Base Plate'!$W$73)) -> 20 | C17: =IF('1-Base Plate'!$W$73>=0,"ton (C)","ton (T)") -> ton (C) | D17: M = | E17: =IF($W$41,"-",'1-Base Plate'!$W$76/100) -> 8 | F17: t.m
A18: Vx = | B18: =SUM($AN$25:$AN$36) -> 3 | C18: ton | D18: Vy = | E18: =SUM($AO$25:$AO$36) -> 1 | F18: ton
A19: Tension bolts = | B19: =$W$56 -> 2 | D19: Σ(T+Q) = | E19: =$W$57 -> 8.899536 | F19: ton
A20: Max (T+Q) = | B20: =$W$58 -> 4.449768 | C20: ton | D20: Design = | E20: ='1-Base Plate'!C8 -> ASD
A22: Pedestal Plan (to scale) :
V24: act | W24: x | X24: y | Y24: T+Q | Z24: tension | AA24: x t | AB24: y t | AC24: F·x | AD24: F·y | AE24: cx | AF24: cy | AG24: ca1 | AH24: ca2 | AI24: side-face? | AJ24: Nsb | AK24: cap | AL24: ratio | AM24: side | AN24: Vx | AO24: Vy | AP24: pair distances (tension bolts) | BB24: x all | BC24: y all | BN24: layer depth | BO24: layer As
V25: ='1-Base Plate'!V37 -> TRUE | W25: ='1-Base Plate'!W37 -> -25 | X25: ='1-Base Plate'!X37 -> -10 | Y25: ='1-Base Plate'!AU37 -> 4.449768 | Z25: =AND(V25,Y25>0.0001) -> TRUE | AA25: =IF(Z25,W25,"") -> -25 | AB25: =IF(Z25,X25,"") -> -10 | AC25: =IF(Z25,Y25*W25,0) -> -111.2442 | AD25: =IF(Z25,Y25*X25,0) -> -44.49768 | AE25: =$W$43/2-ABS(W25) -> 15 | AF25: =$W$44/2-ABS(X25) -> 20 | AG25: =IF(Z25,MIN(AE25,AF25),"") -> 15 | AH25: =IF(Z25,MAX(AE25,AF25),"") -> 20 | AI25: =IF(Z25,$W$47>2.5*AG25,FALSE) -> TRUE | AJ25: =IF(AI25,13*AG25*10*SQRT($W$49*100)*SQRT($W$46)/1000*IF(AH25<3*AG25,(1+AH25/AG25)/4,1),"") -> 331.04925 | AK25: =IF(AI25,$W$52*AJ25/$W$53,"") -> 165.52462 | AL25: =IF(AI25,Y25*9.81/AK25,"") -> 0.26372043 | AM25: =IF(Z25,SIGN(IF($W$42,W25,X25)),0) -> -1 | AN25: ='1-Base Plate'!AC37 -> 0.75 | AO25: ='1-Base Plate'!AD37 -> 0.25 | AQ25: =IF(AND(Z25,Z26),SQRT((W25-W26)^2+(X25-X26)^2),"") | AR25: =IF(AND(Z25,Z27),SQRT((W25-W27)^2+(X25-X27)^2),"") | AS25: =IF(AND(Z25,Z28),SQRT((W25-W28)^2+(X25-X28)^2),"") -> 20 | AT25: =IF(AND(Z25,Z29),SQRT((W25-W29)^2+(X25-X29)^2),"") | AU25: =IF(AND(Z25,Z30),SQRT((W25-W30)^2+(X25-X30)^2),"") | AV25: =IF(AND(Z25,Z31),SQRT((W25-W31)^2+(X25-X31)^2),"") | AW25: =IF(AND(Z25,Z32),SQRT((W25-W32)^2+(X25-X32)^2),"") | AX25: =IF(AND(Z25,Z33),SQRT((W25-W33)^2+(X25-X33)^2),"") | AY25: =IF(AND(Z25,Z34),SQRT((W25-W34)^2+(X25-X34)^2),"") | AZ25: =IF(AND(Z25,Z35),SQRT((W25-W35)^2+(X25-X35)^2),"") | BA25: =IF(AND(Z25,Z36),SQRT((W25-W36)^2+(X25-X36)^2),"") | BB25: =IF(V25,W25,"") -> -25 | BC25: =IF(V25,X25,"") -> -10 | BN25: =IF(0=0,$W$144,IF(0<=$W$170,$W$144+0*($W$145-$W$144)/($W$170+1),IF(0=$W$170+1,$W$145,0))) -> 6.8 | BO25: =IF(0=0,$W$169*$W$152,IF(0<=$W$170,2*$W$152,IF(0=$W$170+1,$W$169*$W$152,0))) -> 12.063716 | BP25: =-1*$W$43/2/$W$193 -> -0.81967213 | BQ25: =-1*$W$44/2/$W$193 -> -0.6147541 | BR25: =-1*'1-Base Plate'!$C$17/2/$W$193 -> -0.6147541 | BS25: =-1*'1-Base Plate'!$C$18/2/$W$193 -> -0.30737705 | BT25: =IF($W$51,-1*($W$43/2-($C$10+$F$10/20))/$W$193,NA()) -> -0.70696721 | BU25: =IF($W$51,-1*($W$44/2-($C$10+$F$10/20))/$W$193,NA()) -> -0.50204918 | BX25: =-($W$43/2+6)/$W$193 -> -0.94262295 | BY25: 0 | CF25: 0 | CG25: =IF(CF25<$W$171,IF(CF25<$W$194,-$W$196/2+CF25*$W$196/($W$194-1),IF(CF25<2*$W$194,-$W$196/2+(CF25-$W$194)*$W$196/($W$194-1),IF(CF25<2*$W$194+$W$195-2,-$W$196/2,$W$196/2)))/$W$193,NA()) -> -0.68032787 | CH25: =IF(CF25<$W$171,IF(CF25<$W$194,-$W$197/2,IF(CF25<2*$W$194,$W$197/2,IF(CF25<2*$W$194+$W$195-2,-$W$197/2+(CF25-2*$W$194+1)*$W$197/($W$195-1),-$W$197/2+(CF25-2*$W$194-($W$195-2)+1)*$W$197/($W$195-1))))/$W$193,NA()) -> -0.47540984 | CI25: =IF(V25,W25/$W$193,NA()) -> -0.51229508 | CJ25: =IF(V25,X25/$W$193,NA()) -> -0.20491803 | CK25: =IF(Z25,TEXT(Y25,"0.00")&" t"," ") -> 4.45 t | CL25: =($W$43/2+6)/$W$193 -> 0.94262295 | CM25: 0 | CN25: X
V26: ='1-Base Plate'!V38 -> TRUE | W26: ='1-Base Plate'!W38 -> 25 | X26: ='1-Base Plate'!X38 -> -10 | Y26: ='1-Base Plate'!AU38 -> 0 | Z26: =AND(V26,Y26>0.0001) -> FALSE | AA26: =IF(Z26,W26,"") | AB26: =IF(Z26,X26,"") | AC26: =IF(Z26,Y26*W26,0) -> 0 | AD26: =IF(Z26,Y26*X26,0) -> 0 | AE26: =$W$43/2-ABS(W26) -> 15 | AF26: =$W$44/2-ABS(X26) -> 20 | AG26: =IF(Z26,MIN(AE26,AF26),"") | AH26: =IF(Z26,MAX(AE26,AF26),"") | AI26: =IF(Z26,$W$47>2.5*AG26,FALSE) -> FALSE | AJ26: =IF(AI26,13*AG26*10*SQRT($W$49*100)*SQRT($W$46)/1000*IF(AH26<3*AG26,(1+AH26/AG26)/4,1),"") | AK26: =IF(AI26,$W$52*AJ26/$W$53,"") | AL26: =IF(AI26,Y26*9.81/AK26,"") | AM26: =IF(Z26,SIGN(IF($W$42,W26,X26)),0) -> 0 | AN26: ='1-Base Plate'!AC38 -> 0.75 | AO26: ='1-Base Plate'!AD38 -> 0.25 | AR26: =IF(AND(Z26,Z27),SQRT((W26-W27)^2+(X26-X27)^2),"") | AS26: =IF(AND(Z26,Z28),SQRT((W26-W28)^2+(X26-X28)^2),"") | AT26: =IF(AND(Z26,Z29),SQRT((W26-W29)^2+(X26-X29)^2),"") | AU26: =IF(AND(Z26,Z30),SQRT((W26-W30)^2+(X26-X30)^2),"") | AV26: =IF(AND(Z26,Z31),SQRT((W26-W31)^2+(X26-X31)^2),"") | AW26: =IF(AND(Z26,Z32),SQRT((W26-W32)^2+(X26-X32)^2),"") | AX26: =IF(AND(Z26,Z33),SQRT((W26-W33)^2+(X26-X33)^2),"") | AY26: =IF(AND(Z26,Z34),SQRT((W26-W34)^2+(X26-X34)^2),"") | AZ26: =IF(AND(Z26,Z35),SQRT((W26-W35)^2+(X26-X35)^2),"") | BA26: =IF(AND(Z26,Z36),SQRT((W26-W36)^2+(X26-X36)^2),"") | BB26: =IF(V26,W26,"") -> 25 | BC26: =IF(V26,X26,"") -> -10 | BN26: =IF(1=0,$W$144,IF(1<=$W$170,$W$144+1*($W$145-$W$144)/($W$170+1),IF(1=$W$170+1,$W$145,0))) -> 20.08 | BO26: =IF(1=0,$W$169*$W$152,IF(1<=$W$170,2*$W$152,IF(1=$W$170+1,$W$169*$W$152,0))) -> 4.0212386 | BP26: =1*$W$43/2/$W$193 -> 0.81967213 | BQ26: =-1*$W$44/2/$W$193 -> -0.6147541 | BR26: =1*'1-Base Plate'!$C$17/2/$W$193 -> 0.6147541 | BS26: =-1*'1-Base Plate'!$C$18/2/$W$193 -> -0.30737705 | BT26: =IF($W$51,1*($W$43/2-($C$10+$F$10/20))/$W$193,NA()) -> 0.70696721 | BU26: =IF($W$51,-1*($W$44/2-($C$10+$F$10/20))/$W$193,NA()) -> -0.50204918 | BX26: =($W$43/2+6)/$W$193 -> 0.94262295 | BY26: 0 | CF26: 1 | CG26: =IF(CF26<$W$171,IF(CF26<$W$194,-$W$196/2+CF26*$W$196/($W$194-1),IF(CF26<2*$W$194,-$W$196/2+(CF26-$W$194)*$W$196/($W$194-1),IF(CF26<2*$W$194+$W$195-2,-$W$196/2,$W$196/2)))/$W$193,NA()) -> -0.40819672 | CH26: =IF(CF26<$W$171,IF(CF26<$W$194,-$W$197/2,IF(CF26<2*$W$194,$W$197/2,IF(CF26<2*$W$194+$W$195-2,-$W$197/2+(CF26-2*$W$194+1)*$W$197/($W$195-1),-$W$197/2+(CF26-2*$W$194-($W$195-2)+1)*$W$197/($W$195-1))))/$W$193,NA()) -> -0.47540984 | CI26: =IF(V26,W26/$W$193,NA()) -> 0.51229508 | CJ26: =IF(V26,X26/$W$193,NA()) -> -0.20491803 | CK26: =IF(Z26,TEXT(Y26,"0.00")&" t"," ") | CL26: 0 | CM26: =($W$44/2+6)/$W$193 -> 0.73770492 | CN26: Y
V27: ='1-Base Plate'!V39 -> TRUE | W27: ='1-Base Plate'!W39 -> 25 | X27: ='1-Base Plate'!X39 -> 10 | Y27: ='1-Base Plate'!AU39 -> 0 | Z27: =AND(V27,Y27>0.0001) -> FALSE | AA27: =IF(Z27,W27,"") | AB27: =IF(Z27,X27,"") | AC27: =IF(Z27,Y27*W27,0) -> 0 | AD27: =IF(Z27,Y27*X27,0) -> 0 | AE27: =$W$43/2-ABS(W27) -> 15 | AF27: =$W$44/2-ABS(X27) -> 20 | AG27: =IF(Z27,MIN(AE27,AF27),"") | AH27: =IF(Z27,MAX(AE27,AF27),"") | AI27: =IF(Z27,$W$47>2.5*AG27,FALSE) -> FALSE | AJ27: =IF(AI27,13*AG27*10*SQRT($W$49*100)*SQRT($W$46)/1000*IF(AH27<3*AG27,(1+AH27/AG27)/4,1),"") | AK27: =IF(AI27,$W$52*AJ27/$W$53,"") | AL27: =IF(AI27,Y27*9.81/AK27,"") | AM27: =IF(Z27,SIGN(IF($W$42,W27,X27)),0) -> 0 | AN27: ='1-Base Plate'!AC39 -> 0.75 | AO27: ='1-Base Plate'!AD39 -> 0.25 | AS27: =IF(AND(Z27,Z28),SQRT((W27-W28)^2+(X27-X28)^2),"") | AT27: =IF(AND(Z27,Z29),SQRT((W27-W29)^2+(X27-X29)^2),"") | AU27: =IF(AND(Z27,Z30),SQRT((W27-W30)^2+(X27-X30)^2),"") | AV27: =IF(AND(Z27,Z31),SQRT((W27-W31)^2+(X27-X31)^2),"") | AW27: =IF(AND(Z27,Z32),SQRT((W27-W32)^2+(X27-X32)^2),"") | AX27: =IF(AND(Z27,Z33),SQRT((W27-W33)^2+(X27-X33)^2),"") | AY27: =IF(AND(Z27,Z34),SQRT((W27-W34)^2+(X27-X34)^2),"") | AZ27: =IF(AND(Z27,Z35),SQRT((W27-W35)^2+(X27-X35)^2),"") | BA27: =IF(AND(Z27,Z36),SQRT((W27-W36)^2+(X27-X36)^2),"") | BB27: =IF(V27,W27,"") -> 25 | BC27: =IF(V27,X27,"") -> 10 | BN27: =IF(2=0,$W$144,IF(2<=$W$170,$W$144+2*($W$145-$W$144)/($W$170+1),IF(2=$W$170+1,$W$145,0))) -> 33.36 | BO27: =IF(2=0,$W$169*$W$152,IF(2<=$W$170,2*$W$152,IF(2=$W$170+1,$W$169*$W$152,0))) -> 4.0212386 | BP27: =1*$W$43/2/$W$193 -> 0.81967213 | BQ27: =1*$W$44/2/$W$193 -> 0.6147541 | BR27: =1*'1-Base Plate'!$C$17/2/$W$193 -> 0.6147541 | BS27: =1*'1-Base Plate'!$C$18/2/$W$193 -> 0.30737705 | BT27: =IF($W$51,1*($W$43/2-($C$10+$F$10/20))/$W$193,NA()) -> 0.70696721 | BU27: =IF($W$51,1*($W$44/2-($C$10+$F$10/20))/$W$193,NA()) -> 0.50204918 | BX27: 0 | BY27: =-($W$44/2+6)/$W$193 -> -0.73770492 | CF27: 2 | CG27: =IF(CF27<$W$171,IF(CF27<$W$194,-$W$196/2+CF27*$W$196/($W$194-1),IF(CF27<2*$W$194,-$W$196/2+(CF27-$W$194)*$W$196/($W$194-1),IF(CF27<2*$W$194+$W$195-2,-$W$196/2,$W$196/2)))/$W$193,NA()) -> -0.13606557 | CH27: =IF(CF27<$W$171,IF(CF27<$W$194,-$W$197/2,IF(CF27<2*$W$194,$W$197/2,IF(CF27<2*$W$194+$W$195-2,-$W$197/2+(CF27-2*$W$194+1)*$W$197/($W$195-1),-$W$197/2+(CF27-2*$W$194-($W$195-2)+1)*$W$197/($W$195-1))))/$W$193,NA()) -> -0.47540984 | CI27: =IF(V27,W27/$W$193,NA()) -> 0.51229508 | CJ27: =IF(V27,X27/$W$193,NA()) -> 0.20491803 | CK27: =IF(Z27,TEXT(Y27,"0.00")&" t"," ") | CL27: 0 | CM27: =-($W$44/2+2)/$W$193 -> -0.6557377 | CN27: ="Bx = "&$W$43&" cm" -> Bx = 80 cm
V28: ='1-Base Plate'!V40 -> TRUE | W28: ='1-Base Plate'!W40 -> -25 | X28: ='1-Base Plate'!X40 -> 10 | Y28: ='1-Base Plate'!AU40 -> 4.449768 | Z28: =AND(V28,Y28>0.0001) -> TRUE | AA28: =IF(Z28,W28,"") -> -25 | AB28: =IF(Z28,X28,"") -> 10 | AC28: =IF(Z28,Y28*W28,0) -> -111.2442 | AD28: =IF(Z28,Y28*X28,0) -> 44.49768 | AE28: =$W$43/2-ABS(W28) -> 15 | AF28: =$W$44/2-ABS(X28) -> 20 | AG28: =IF(Z28,MIN(AE28,AF28),"") -> 15 | AH28: =IF(Z28,MAX(AE28,AF28),"") -> 20 | AI28: =IF(Z28,$W$47>2.5*AG28,FALSE) -> TRUE | AJ28: =IF(AI28,13*AG28*10*SQRT($W$49*100)*SQRT($W$46)/1000*IF(AH28<3*AG28,(1+AH28/AG28)/4,1),"") -> 331.04925 | AK28: =IF(AI28,$W$52*AJ28/$W$53,"") -> 165.52462 | AL28: =IF(AI28,Y28*9.81/AK28,"") -> 0.26372043 | AM28: =IF(Z28,SIGN(IF($W$42,W28,X28)),0) -> -1 | AN28: ='1-Base Plate'!AC40 -> 0.75 | AO28: ='1-Base Plate'!AD40 -> 0.25 | AT28: =IF(AND(Z28,Z29),SQRT((W28-W29)^2+(X28-X29)^2),"") | AU28: =IF(AND(Z28,Z30),SQRT((W28-W30)^2+(X28-X30)^2),"") | AV28: =IF(AND(Z28,Z31),SQRT((W28-W31)^2+(X28-X31)^2),"") | AW28: =IF(AND(Z28,Z32),SQRT((W28-W32)^2+(X28-X32)^2),"") | AX28: =IF(AND(Z28,Z33),SQRT((W28-W33)^2+(X28-X33)^2),"") | AY28: =IF(AND(Z28,Z34),SQRT((W28-W34)^2+(X28-X34)^2),"") | AZ28: =IF(AND(Z28,Z35),SQRT((W28-W35)^2+(X28-X35)^2),"") | BA28: =IF(AND(Z28,Z36),SQRT((W28-W36)^2+(X28-X36)^2),"") | BB28: =IF(V28,W28,"") -> -25 | BC28: =IF(V28,X28,"") -> 10 | BN28: =IF(3=0,$W$144,IF(3<=$W$170,$W$144+3*($W$145-$W$144)/($W$170+1),IF(3=$W$170+1,$W$145,0))) -> 46.64 | BO28: =IF(3=0,$W$169*$W$152,IF(3<=$W$170,2*$W$152,IF(3=$W$170+1,$W$169*$W$152,0))) -> 4.0212386 | BP28: =-1*$W$43/2/$W$193 -> -0.81967213 | BQ28: =1*$W$44/2/$W$193 -> 0.6147541 | BR28: =-1*'1-Base Plate'!$C$17/2/$W$193 -> -0.6147541 | BS28: =1*'1-Base Plate'!$C$18/2/$W$193 -> 0.30737705 | BT28: =IF($W$51,-1*($W$43/2-($C$10+$F$10/20))/$W$193,NA()) -> -0.70696721 | BU28: =IF($W$51,1*($W$44/2-($C$10+$F$10/20))/$W$193,NA()) -> 0.50204918 | BX28: 0 | BY28: =($W$44/2+6)/$W$193 -> 0.73770492 | CF28: 3 | CG28: =IF(CF28<$W$171,IF(CF28<$W$194,-$W$196/2+CF28*$W$196/($W$194-1),IF(CF28<2*$W$194,-$W$196/2+(CF28-$W$194)*$W$196/($W$194-1),IF(CF28<2*$W$194+$W$195-2,-$W$196/2,$W$196/2)))/$W$193,NA()) -> 0.13606557 | CH28: =IF(CF28<$W$171,IF(CF28<$W$194,-$W$197/2,IF(CF28<2*$W$194,$W$197/2,IF(CF28<2*$W$194+$W$195-2,-$W$197/2+(CF28-2*$W$194+1)*$W$197/($W$195-1),-$W$197/2+(CF28-2*$W$194-($W$195-2)+1)*$W$197/($W$195-1))))/$W$193,NA()) -> -0.47540984 | CI28: =IF(V28,W28/$W$193,NA()) -> -0.51229508 | CJ28: =IF(V28,X28/$W$193,NA()) -> 0.20491803 | CK28: =IF(Z28,TEXT(Y28,"0.00")&" t"," ") -> 4.45 t | CL28: =-($W$43/2+1)/$W$193 -> -0.84016393 | CM28: 0 | CN28: ="By = "&$W$44&" cm" -> By = 60 cm
V29: ='1-Base Plate'!V41 -> FALSE | W29: ='1-Base Plate'!W41 -> 0 | X29: ='1-Base Plate'!X41 -> 0 | Y29: ='1-Base Plate'!AU41 -> 0 | Z29: =AND(V29,Y29>0.0001) -> FALSE | AA29: =IF(Z29,W29,"") | AB29: =IF(Z29,X29,"") | AC29: =IF(Z29,Y29*W29,0) -> 0 | AD29: =IF(Z29,Y29*X29,0) -> 0 | AE29: =$W$43/2-ABS(W29) -> 40 | AF29: =$W$44/2-ABS(X29) -> 30 | AG29: =IF(Z29,MIN(AE29,AF29),"") | AH29: =IF(Z29,MAX(AE29,AF29),"") | AI29: =IF(Z29,$W$47>2.5*AG29,FALSE) -> FALSE | AJ29: =IF(AI29,13*AG29*10*SQRT($W$49*100)*SQRT($W$46)/1000*IF(AH29<3*AG29,(1+AH29/AG29)/4,1),"") | AK29: =IF(AI29,$W$52*AJ29/$W$53,"") | AL29: =IF(AI29,Y29*9.81/AK29,"") | AM29: =IF(Z29,SIGN(IF($W$42,W29,X29)),0) -> 0 | AN29: ='1-Base Plate'!AC41 -> 0 | AO29: ='1-Base Plate'!AD41 -> 0 | AU29: =IF(AND(Z29,Z30),SQRT((W29-W30)^2+(X29-X30)^2),"") | AV29: =IF(AND(Z29,Z31),SQRT((W29-W31)^2+(X29-X31)^2),"") | AW29: =IF(AND(Z29,Z32),SQRT((W29-W32)^2+(X29-X32)^2),"") | AX29: =IF(AND(Z29,Z33),SQRT((W29-W33)^2+(X29-X33)^2),"") | AY29: =IF(AND(Z29,Z34),SQRT((W29-W34)^2+(X29-X34)^2),"") | AZ29: =IF(AND(Z29,Z35),SQRT((W29-W35)^2+(X29-X35)^2),"") | BA29: =IF(AND(Z29,Z36),SQRT((W29-W36)^2+(X29-X36)^2),"") | BB29: =IF(V29,W29,"") | BC29: =IF(V29,X29,"") | BN29: =IF(4=0,$W$144,IF(4<=$W$170,$W$144+4*($W$145-$W$144)/($W$170+1),IF(4=$W$170+1,$W$145,0))) -> 59.92 | BO29: =IF(4=0,$W$169*$W$152,IF(4<=$W$170,2*$W$152,IF(4=$W$170+1,$W$169*$W$152,0))) -> 4.0212386 | BP29: =-1*$W$43/2/$W$193 -> -0.81967213 | BQ29: =-1*$W$44/2/$W$193 -> -0.6147541 | BR29: =-1*'1-Base Plate'!$C$17/2/$W$193 -> -0.6147541 | BS29: =-1*'1-Base Plate'!$C$18/2/$W$193 -> -0.30737705 | BT29: =IF($W$51,-1*($W$43/2-($C$10+$F$10/20))/$W$193,NA()) -> -0.70696721 | BU29: =IF($W$51,-1*($W$44/2-($C$10+$F$10/20))/$W$193,NA()) -> -0.50204918 | CF29: 4 | CG29: =IF(CF29<$W$171,IF(CF29<$W$194,-$W$196/2+CF29*$W$196/($W$194-1),IF(CF29<2*$W$194,-$W$196/2+(CF29-$W$194)*$W$196/($W$194-1),IF(CF29<2*$W$194+$W$195-2,-$W$196/2,$W$196/2)))/$W$193,NA()) -> 0.40819672 | CH29: =IF(CF29<$W$171,IF(CF29<$W$194,-$W$197/2,IF(CF29<2*$W$194,$W$197/2,IF(CF29<2*$W$194+$W$195-2,-$W$197/2+(CF29-2*$W$194+1)*$W$197/($W$195-1),-$W$197/2+(CF29-2*$W$194-($W$195-2)+1)*$W$197/($W$195-1))))/$W$193,NA()) -> -0.47540984 | CI29: =IF(V29,W29/$W$193,NA()) -> #N/A | CJ29: =IF(V29,X29/$W$193,NA()) -> #N/A | CK29: =IF(Z29,TEXT(Y29,"0.00")&" t"," ")
V30: ='1-Base Plate'!V42 -> FALSE | W30: ='1-Base Plate'!W42 -> 0 | X30: ='1-Base Plate'!X42 -> 0 | Y30: ='1-Base Plate'!AU42 -> 0 | Z30: =AND(V30,Y30>0.0001) -> FALSE | AA30: =IF(Z30,W30,"") | AB30: =IF(Z30,X30,"") | AC30: =IF(Z30,Y30*W30,0) -> 0 | AD30: =IF(Z30,Y30*X30,0) -> 0 | AE30: =$W$43/2-ABS(W30) -> 40 | AF30: =$W$44/2-ABS(X30) -> 30 | AG30: =IF(Z30,MIN(AE30,AF30),"") | AH30: =IF(Z30,MAX(AE30,AF30),"") | AI30: =IF(Z30,$W$47>2.5*AG30,FALSE) -> FALSE | AJ30: =IF(AI30,13*AG30*10*SQRT($W$49*100)*SQRT($W$46)/1000*IF(AH30<3*AG30,(1+AH30/AG30)/4,1),"") | AK30: =IF(AI30,$W$52*AJ30/$W$53,"") | AL30: =IF(AI30,Y30*9.81/AK30,"") | AM30: =IF(Z30,SIGN(IF($W$42,W30,X30)),0) -> 0 | AN30: ='1-Base Plate'!AC42 -> 0 | AO30: ='1-Base Plate'!AD42 -> 0 | AV30: =IF(AND(Z30,Z31),SQRT((W30-W31)^2+(X30-X31)^2),"") | AW30: =IF(AND(Z30,Z32),SQRT((W30-W32)^2+(X30-X32)^2),"") | AX30: =IF(AND(Z30,Z33),SQRT((W30-W33)^2+(X30-X33)^2),"") | AY30: =IF(AND(Z30,Z34),SQRT((W30-W34)^2+(X30-X34)^2),"") | AZ30: =IF(AND(Z30,Z35),SQRT((W30-W35)^2+(X30-X35)^2),"") | BA30: =IF(AND(Z30,Z36),SQRT((W30-W36)^2+(X30-X36)^2),"") | BB30: =IF(V30,W30,"") | BC30: =IF(V30,X30,"") | BN30: =IF(5=0,$W$144,IF(5<=$W$170,$W$144+5*($W$145-$W$144)/($W$170+1),IF(5=$W$170+1,$W$145,0))) -> 73.2 | BO30: =IF(5=0,$W$169*$W$152,IF(5<=$W$170,2*$W$152,IF(5=$W$170+1,$W$169*$W$152,0))) -> 12.063716 | CF30: 5 | CG30: =IF(CF30<$W$171,IF(CF30<$W$194,-$W$196/2+CF30*$W$196/($W$194-1),IF(CF30<2*$W$194,-$W$196/2+(CF30-$W$194)*$W$196/($W$194-1),IF(CF30<2*$W$194+$W$195-2,-$W$196/2,$W$196/2)))/$W$193,NA()) -> 0.68032787 | CH30: =IF(CF30<$W$171,IF(CF30<$W$194,-$W$197/2,IF(CF30<2*$W$194,$W$197/2,IF(CF30<2*$W$194+$W$195-2,-$W$197/2+(CF30-2*$W$194+1)*$W$197/($W$195-1),-$W$197/2+(CF30-2*$W$194-($W$195-2)+1)*$W$197/($W$195-1))))/$W$193,NA()) -> -0.47540984 | CI30: =IF(V30,W30/$W$193,NA()) -> #N/A | CJ30: =IF(V30,X30/$W$193,NA()) -> #N/A | CK30: =IF(Z30,TEXT(Y30,"0.00")&" t"," ")
V31: ='1-Base Plate'!V43 -> FALSE | W31: ='1-Base Plate'!W43 -> 0 | X31: ='1-Base Plate'!X43 -> 0 | Y31: ='1-Base Plate'!AU43 -> 0 | Z31: =AND(V31,Y31>0.0001) -> FALSE | AA31: =IF(Z31,W31,"") | AB31: =IF(Z31,X31,"") | AC31: =IF(Z31,Y31*W31,0) -> 0 | AD31: =IF(Z31,Y31*X31,0) -> 0 | AE31: =$W$43/2-ABS(W31) -> 40 | AF31: =$W$44/2-ABS(X31) -> 30 | AG31: =IF(Z31,MIN(AE31,AF31),"") | AH31: =IF(Z31,MAX(AE31,AF31),"") | AI31: =IF(Z31,$W$47>2.5*AG31,FALSE) -> FALSE | AJ31: =IF(AI31,13*AG31*10*SQRT($W$49*100)*SQRT($W$46)/1000*IF(AH31<3*AG31,(1+AH31/AG31)/4,1),"") | AK31: =IF(AI31,$W$52*AJ31/$W$53,"") | AL31: =IF(AI31,Y31*9.81/AK31,"") | AM31: =IF(Z31,SIGN(IF($W$42,W31,X31)),0) -> 0 | AN31: ='1-Base Plate'!AC43 -> 0 | AO31: ='1-Base Plate'!AD43 -> 0 | AW31: =IF(AND(Z31,Z32),SQRT((W31-W32)^2+(X31-X32)^2),"") | AX31: =IF(AND(Z31,Z33),SQRT((W31-W33)^2+(X31-X33)^2),"") | AY31: =IF(AND(Z31,Z34),SQRT((W31-W34)^2+(X31-X34)^2),"") | AZ31: =IF(AND(Z31,Z35),SQRT((W31-W35)^2+(X31-X35)^2),"") | BA31: =IF(AND(Z31,Z36),SQRT((W31-W36)^2+(X31-X36)^2),"") | BB31: =IF(V31,W31,"") | BC31: =IF(V31,X31,"") | BN31: =IF(6=0,$W$144,IF(6<=$W$170,$W$144+6*($W$145-$W$144)/($W$170+1),IF(6=$W$170+1,$W$145,0))) -> 0 | BO31: =IF(6=0,$W$169*$W$152,IF(6<=$W$170,2*$W$152,IF(6=$W$170+1,$W$169*$W$152,0))) -> 0 | CF31: 6 | CG31: =IF(CF31<$W$171,IF(CF31<$W$194,-$W$196/2+CF31*$W$196/($W$194-1),IF(CF31<2*$W$194,-$W$196/2+(CF31-$W$194)*$W$196/($W$194-1),IF(CF31<2*$W$194+$W$195-2,-$W$196/2,$W$196/2)))/$W$193,NA()) -> -0.68032787 | CH31: =IF(CF31<$W$171,IF(CF31<$W$194,-$W$197/2,IF(CF31<2*$W$194,$W$197/2,IF(CF31<2*$W$194+$W$195-2,-$W$197/2+(CF31-2*$W$194+1)*$W$197/($W$195-1),-$W$197/2+(CF31-2*$W$194-($W$195-2)+1)*$W$197/($W$195-1))))/$W$193,NA()) -> 0.47540984 | CI31: =IF(V31,W31/$W$193,NA()) -> #N/A | CJ31: =IF(V31,X31/$W$193,NA()) -> #N/A | CK31: =IF(Z31,TEXT(Y31,"0.00")&" t"," ")
V32: ='1-Base Plate'!V44 -> FALSE | W32: ='1-Base Plate'!W44 -> 0 | X32: ='1-Base Plate'!X44 -> 0 | Y32: ='1-Base Plate'!AU44 -> 0 | Z32: =AND(V32,Y32>0.0001) -> FALSE | AA32: =IF(Z32,W32,"") | AB32: =IF(Z32,X32,"") | AC32: =IF(Z32,Y32*W32,0) -> 0 | AD32: =IF(Z32,Y32*X32,0) -> 0 | AE32: =$W$43/2-ABS(W32) -> 40 | AF32: =$W$44/2-ABS(X32) -> 30 | AG32: =IF(Z32,MIN(AE32,AF32),"") | AH32: =IF(Z32,MAX(AE32,AF32),"") | AI32: =IF(Z32,$W$47>2.5*AG32,FALSE) -> FALSE | AJ32: =IF(AI32,13*AG32*10*SQRT($W$49*100)*SQRT($W$46)/1000*IF(AH32<3*AG32,(1+AH32/AG32)/4,1),"") | AK32: =IF(AI32,$W$52*AJ32/$W$53,"") | AL32: =IF(AI32,Y32*9.81/AK32,"") | AM32: =IF(Z32,SIGN(IF($W$42,W32,X32)),0) -> 0 | AN32: ='1-Base Plate'!AC44 -> 0 | AO32: ='1-Base Plate'!AD44 -> 0 | AX32: =IF(AND(Z32,Z33),SQRT((W32-W33)^2+(X32-X33)^2),"") | AY32: =IF(AND(Z32,Z34),SQRT((W32-W34)^2+(X32-X34)^2),"") | AZ32: =IF(AND(Z32,Z35),SQRT((W32-W35)^2+(X32-X35)^2),"") | BA32: =IF(AND(Z32,Z36),SQRT((W32-W36)^2+(X32-X36)^2),"") | BB32: =IF(V32,W32,"") | BC32: =IF(V32,X32,"") | BN32: =IF(7=0,$W$144,IF(7<=$W$170,$W$144+7*($W$145-$W$144)/($W$170+1),IF(7=$W$170+1,$W$145,0))) -> 0 | BO32: =IF(7=0,$W$169*$W$152,IF(7<=$W$170,2*$W$152,IF(7=$W$170+1,$W$169*$W$152,0))) -> 0 | CF32: 7 | CG32: =IF(CF32<$W$171,IF(CF32<$W$194,-$W$196/2+CF32*$W$196/($W$194-1),IF(CF32<2*$W$194,-$W$196/2+(CF32-$W$194)*$W$196/($W$194-1),IF(CF32<2*$W$194+$W$195-2,-$W$196/2,$W$196/2)))/$W$193,NA()) -> -0.40819672 | CH32: =IF(CF32<$W$171,IF(CF32<$W$194,-$W$197/2,IF(CF32<2*$W$194,$W$197/2,IF(CF32<2*$W$194+$W$195-2,-$W$197/2+(CF32-2*$W$194+1)*$W$197/($W$195-1),-$W$197/2+(CF32-2*$W$194-($W$195-2)+1)*$W$197/($W$195-1))))/$W$193,NA()) -> 0.47540984 | CI32: =IF(V32,W32/$W$193,NA()) -> #N/A | CJ32: =IF(V32,X32/$W$193,NA()) -> #N/A | CK32: =IF(Z32,TEXT(Y32,"0.00")&" t"," ")
V33: ='1-Base Plate'!V45 -> FALSE | W33: ='1-Base Plate'!W45 -> 0 | X33: ='1-Base Plate'!X45 -> 0 | Y33: ='1-Base Plate'!AU45 -> 0 | Z33: =AND(V33,Y33>0.0001) -> FALSE | AA33: =IF(Z33,W33,"") | AB33: =IF(Z33,X33,"") | AC33: =IF(Z33,Y33*W33,0) -> 0 | AD33: =IF(Z33,Y33*X33,0) -> 0 | AE33: =$W$43/2-ABS(W33) -> 40 | AF33: =$W$44/2-ABS(X33) -> 30 | AG33: =IF(Z33,MIN(AE33,AF33),"") | AH33: =IF(Z33,MAX(AE33,AF33),"") | AI33: =IF(Z33,$W$47>2.5*AG33,FALSE) -> FALSE | AJ33: =IF(AI33,13*AG33*10*SQRT($W$49*100)*SQRT($W$46)/1000*IF(AH33<3*AG33,(1+AH33/AG33)/4,1),"") | AK33: =IF(AI33,$W$52*AJ33/$W$53,"") | AL33: =IF(AI33,Y33*9.81/AK33,"") | AM33: =IF(Z33,SIGN(IF($W$42,W33,X33)),0) -> 0 | AN33: ='1-Base Plate'!AC45 -> 0 | AO33: ='1-Base Plate'!AD45 -> 0 | AY33: =IF(AND(Z33,Z34),SQRT((W33-W34)^2+(X33-X34)^2),"") | AZ33: =IF(AND(Z33,Z35),SQRT((W33-W35)^2+(X33-X35)^2),"") | BA33: =IF(AND(Z33,Z36),SQRT((W33-W36)^2+(X33-X36)^2),"") | BB33: =IF(V33,W33,"") | BC33: =IF(V33,X33,"") | BN33: =IF(8=0,$W$144,IF(8<=$W$170,$W$144+8*($W$145-$W$144)/($W$170+1),IF(8=$W$170+1,$W$145,0))) -> 0 | BO33: =IF(8=0,$W$169*$W$152,IF(8<=$W$170,2*$W$152,IF(8=$W$170+1,$W$169*$W$152,0))) -> 0 | CF33: 8 | CG33: =IF(CF33<$W$171,IF(CF33<$W$194,-$W$196/2+CF33*$W$196/($W$194-1),IF(CF33<2*$W$194,-$W$196/2+(CF33-$W$194)*$W$196/($W$194-1),IF(CF33<2*$W$194+$W$195-2,-$W$196/2,$W$196/2)))/$W$193,NA()) -> -0.13606557 | CH33: =IF(CF33<$W$171,IF(CF33<$W$194,-$W$197/2,IF(CF33<2*$W$194,$W$197/2,IF(CF33<2*$W$194+$W$195-2,-$W$197/2+(CF33-2*$W$194+1)*$W$197/($W$195-1),-$W$197/2+(CF33-2*$W$194-($W$195-2)+1)*$W$197/($W$195-1))))/$W$193,NA()) -> 0.47540984 | CI33: =IF(V33,W33/$W$193,NA()) -> #N/A | CJ33: =IF(V33,X33/$W$193,NA()) -> #N/A | CK33: =IF(Z33,TEXT(Y33,"0.00")&" t"," ")
V34: ='1-Base Plate'!V46 -> FALSE | W34: ='1-Base Plate'!W46 -> 0 | X34: ='1-Base Plate'!X46 -> 0 | Y34: ='1-Base Plate'!AU46 -> 0 | Z34: =AND(V34,Y34>0.0001) -> FALSE | AA34: =IF(Z34,W34,"") | AB34: =IF(Z34,X34,"") | AC34: =IF(Z34,Y34*W34,0) -> 0 | AD34: =IF(Z34,Y34*X34,0) -> 0 | AE34: =$W$43/2-ABS(W34) -> 40 | AF34: =$W$44/2-ABS(X34) -> 30 | AG34: =IF(Z34,MIN(AE34,AF34),"") | AH34: =IF(Z34,MAX(AE34,AF34),"") | AI34: =IF(Z34,$W$47>2.5*AG34,FALSE) -> FALSE | AJ34: =IF(AI34,13*AG34*10*SQRT($W$49*100)*SQRT($W$46)/1000*IF(AH34<3*AG34,(1+AH34/AG34)/4,1),"") | AK34: =IF(AI34,$W$52*AJ34/$W$53,"") | AL34: =IF(AI34,Y34*9.81/AK34,"") | AM34: =IF(Z34,SIGN(IF($W$42,W34,X34)),0) -> 0 | AN34: ='1-Base Plate'!AC46 -> 0 | AO34: ='1-Base Plate'!AD46 -> 0 | AZ34: =IF(AND(Z34,Z35),SQRT((W34-W35)^2+(X34-X35)^2),"") | BA34: =IF(AND(Z34,Z36),SQRT((W34-W36)^2+(X34-X36)^2),"") | BB34: =IF(V34,W34,"") | BC34: =IF(V34,X34,"") | BN34: =IF(9=0,$W$144,IF(9<=$W$170,$W$144+9*($W$145-$W$144)/($W$170+1),IF(9=$W$170+1,$W$145,0))) -> 0 | BO34: =IF(9=0,$W$169*$W$152,IF(9<=$W$170,2*$W$152,IF(9=$W$170+1,$W$169*$W$152,0))) -> 0 | CF34: 9 | CG34: =IF(CF34<$W$171,IF(CF34<$W$194,-$W$196/2+CF34*$W$196/($W$194-1),IF(CF34<2*$W$194,-$W$196/2+(CF34-$W$194)*$W$196/($W$194-1),IF(CF34<2*$W$194+$W$195-2,-$W$196/2,$W$196/2)))/$W$193,NA()) -> 0.13606557 | CH34: =IF(CF34<$W$171,IF(CF34<$W$194,-$W$197/2,IF(CF34<2*$W$194,$W$197/2,IF(CF34<2*$W$194+$W$195-2,-$W$197/2+(CF34-2*$W$194+1)*$W$197/($W$195-1),-$W$197/2+(CF34-2*$W$194-($W$195-2)+1)*$W$197/($W$195-1))))/$W$193,NA()) -> 0.47540984 | CI34: =IF(V34,W34/$W$193,NA()) -> #N/A | CJ34: =IF(V34,X34/$W$193,NA()) -> #N/A | CK34: =IF(Z34,TEXT(Y34,"0.00")&" t"," ")
V35: ='1-Base Plate'!V47 -> FALSE | W35: ='1-Base Plate'!W47 -> 0 | X35: ='1-Base Plate'!X47 -> 0 | Y35: ='1-Base Plate'!AU47 -> 0 | Z35: =AND(V35,Y35>0.0001) -> FALSE | AA35: =IF(Z35,W35,"") | AB35: =IF(Z35,X35,"") | AC35: =IF(Z35,Y35*W35,0) -> 0 | AD35: =IF(Z35,Y35*X35,0) -> 0 | AE35: =$W$43/2-ABS(W35) -> 40 | AF35: =$W$44/2-ABS(X35) -> 30 | AG35: =IF(Z35,MIN(AE35,AF35),"") | AH35: =IF(Z35,MAX(AE35,AF35),"") | AI35: =IF(Z35,$W$47>2.5*AG35,FALSE) -> FALSE | AJ35: =IF(AI35,13*AG35*10*SQRT($W$49*100)*SQRT($W$46)/1000*IF(AH35<3*AG35,(1+AH35/AG35)/4,1),"") | AK35: =IF(AI35,$W$52*AJ35/$W$53,"") | AL35: =IF(AI35,Y35*9.81/AK35,"") | AM35: =IF(Z35,SIGN(IF($W$42,W35,X35)),0) -> 0 | AN35: ='1-Base Plate'!AC47 -> 0 | AO35: ='1-Base Plate'!AD47 -> 0 | BA35: =IF(AND(Z35,Z36),SQRT((W35-W36)^2+(X35-X36)^2),"") | BB35: =IF(V35,W35,"") | BC35: =IF(V35,X35,"") | BN35: =IF(10=0,$W$144,IF(10<=$W$170,$W$144+10*($W$145-$W$144)/($W$170+1),IF(10=$W$170+1,$W$145,0))) -> 0 | BO35: =IF(10=0,$W$169*$W$152,IF(10<=$W$170,2*$W$152,IF(10=$W$170+1,$W$169*$W$152,0))) -> 0 | CF35: 10 | CG35: =IF(CF35<$W$171,IF(CF35<$W$194,-$W$196/2+CF35*$W$196/($W$194-1),IF(CF35<2*$W$194,-$W$196/2+(CF35-$W$194)*$W$196/($W$194-1),IF(CF35<2*$W$194+$W$195-2,-$W$196/2,$W$196/2)))/$W$193,NA()) -> 0.40819672 | CH35: =IF(CF35<$W$171,IF(CF35<$W$194,-$W$197/2,IF(CF35<2*$W$194,$W$197/2,IF(CF35<2*$W$194+$W$195-2,-$W$197/2+(CF35-2*$W$194+1)*$W$197/($W$195-1),-$W$197/2+(CF35-2*$W$194-($W$195-2)+1)*$W$197/($W$195-1))))/$W$193,NA()) -> 0.47540984 | CI35: =IF(V35,W35/$W$193,NA()) -> #N/A | CJ35: =IF(V35,X35/$W$193,NA()) -> #N/A | CK35: =IF(Z35,TEXT(Y35,"0.00")&" t"," ")
V36: ='1-Base Plate'!V48 -> FALSE | W36: ='1-Base Plate'!W48 -> 0 | X36: ='1-Base Plate'!X48 -> 0 | Y36: ='1-Base Plate'!AU48 -> 0 | Z36: =AND(V36,Y36>0.0001) -> FALSE | AA36: =IF(Z36,W36,"") | AB36: =IF(Z36,X36,"") | AC36: =IF(Z36,Y36*W36,0) -> 0 | AD36: =IF(Z36,Y36*X36,0) -> 0 | AE36: =$W$43/2-ABS(W36) -> 40 | AF36: =$W$44/2-ABS(X36) -> 30 | AG36: =IF(Z36,MIN(AE36,AF36),"") | AH36: =IF(Z36,MAX(AE36,AF36),"") | AI36: =IF(Z36,$W$47>2.5*AG36,FALSE) -> FALSE | AJ36: =IF(AI36,13*AG36*10*SQRT($W$49*100)*SQRT($W$46)/1000*IF(AH36<3*AG36,(1+AH36/AG36)/4,1),"") | AK36: =IF(AI36,$W$52*AJ36/$W$53,"") | AL36: =IF(AI36,Y36*9.81/AK36,"") | AM36: =IF(Z36,SIGN(IF($W$42,W36,X36)),0) -> 0 | AN36: ='1-Base Plate'!AC48 -> 0 | AO36: ='1-Base Plate'!AD48 -> 0 | BB36: =IF(V36,W36,"") | BC36: =IF(V36,X36,"") | BN36: =IF(11=0,$W$144,IF(11<=$W$170,$W$144+11*($W$145-$W$144)/($W$170+1),IF(11=$W$170+1,$W$145,0))) -> 0 | BO36: =IF(11=0,$W$169*$W$152,IF(11<=$W$170,2*$W$152,IF(11=$W$170+1,$W$169*$W$152,0))) -> 0 | CF36: 11 | CG36: =IF(CF36<$W$171,IF(CF36<$W$194,-$W$196/2+CF36*$W$196/($W$194-1),IF(CF36<2*$W$194,-$W$196/2+(CF36-$W$194)*$W$196/($W$194-1),IF(CF36<2*$W$194+$W$195-2,-$W$196/2,$W$196/2)))/$W$193,NA()) -> 0.68032787 | CH36: =IF(CF36<$W$171,IF(CF36<$W$194,-$W$197/2,IF(CF36<2*$W$194,$W$197/2,IF(CF36<2*$W$194+$W$195-2,-$W$197/2+(CF36-2*$W$194+1)*$W$197/($W$195-1),-$W$197/2+(CF36-2*$W$194-($W$195-2)+1)*$W$197/($W$195-1))))/$W$193,NA()) -> 0.47540984 | CI36: =IF(V36,W36/$W$193,NA()) -> #N/A | CJ36: =IF(V36,X36/$W$193,NA()) -> #N/A | CK36: =IF(Z36,TEXT(Y36,"0.00")&" t"," ")
CF37: 12 | CG37: =IF(CF37<$W$171,IF(CF37<$W$194,-$W$196/2+CF37*$W$196/($W$194-1),IF(CF37<2*$W$194,-$W$196/2+(CF37-$W$194)*$W$196/($W$194-1),IF(CF37<2*$W$194+$W$195-2,-$W$196/2,$W$196/2)))/$W$193,NA()) -> -0.68032787 | CH37: =IF(CF37<$W$171,IF(CF37<$W$194,-$W$197/2,IF(CF37<2*$W$194,$W$197/2,IF(CF37<2*$W$194+$W$195-2,-$W$197/2+(CF37-2*$W$194+1)*$W$197/($W$195-1),-$W$197/2+(CF37-2*$W$194-($W$195-2)+1)*$W$197/($W$195-1))))/$W$193,NA()) -> -0.2852459
CF38: 13 | CG38: =IF(CF38<$W$171,IF(CF38<$W$194,-$W$196/2+CF38*$W$196/($W$194-1),IF(CF38<2*$W$194,-$W$196/2+(CF38-$W$194)*$W$196/($W$194-1),IF(CF38<2*$W$194+$W$195-2,-$W$196/2,$W$196/2)))/$W$193,NA()) -> -0.68032787 | CH38: =IF(CF38<$W$171,IF(CF38<$W$194,-$W$197/2,IF(CF38<2*$W$194,$W$197/2,IF(CF38<2*$W$194+$W$195-2,-$W$197/2+(CF38-2*$W$194+1)*$W$197/($W$195-1),-$W$197/2+(CF38-2*$W$194-($W$195-2)+1)*$W$197/($W$195-1))))/$W$193,NA()) -> -0.095081967
V39: HELPERS (hidden) | CF39: 14 | CG39: =IF(CF39<$W$171,IF(CF39<$W$194,-$W$196/2+CF39*$W$196/($W$194-1),IF(CF39<2*$W$194,-$W$196/2+(CF39-$W$194)*$W$196/($W$194-1),IF(CF39<2*$W$194+$W$195-2,-$W$196/2,$W$196/2)))/$W$193,NA()) -> -0.68032787 | CH39: =IF(CF39<$W$171,IF(CF39<$W$194,-$W$197/2,IF(CF39<2*$W$194,$W$197/2,IF(CF39<2*$W$194+$W$195-2,-$W$197/2+(CF39-2*$W$194+1)*$W$197/($W$195-1),-$W$197/2+(CF39-2*$W$194-($W$195-2)+1)*$W$197/($W$195-1))))/$W$193,NA()) -> 0.095081967
